Workbook

Sheet 0 logica
A1: Regresión logística para predecir un sí o un no: el caso de riesgo de crédito (german credit)
A2: Preparado por David Díaz, con asistencia de Claude (Anthropic).
A4: Este archivo acompaña la clase en que pasamos de predecir un número (ventas, retornos, precio de una casa) a predecir una categoría: si un cliente va a pagar su crédito o no. La idea es hacer todo con los dedos, sobre una tabla real de 1.000 clientes de un banco alemán, para que no quede ninguna caja negra: cada número que aparece sale de una fórmula que se puede leer, y los pesos del modelo se pueden encontrar en vivo con Solver.
A5: El recorrido sigue el orden de la clase. Primero (hoja 4) intentamos resolver el problema con la misma regresión lineal de las clases anteriores y vemos qué sale mal: las predicciones no viven entre 0 y 1. Después le aplicamos a esa recta una función que la aplasta al rango correcto, la función logística, y ganamos dos cosas: predicciones que se pueden leer como probabilidades y un umbral, que por ahora fijamos en 50%, para colapsar la probabilidad en un sí o un no.
A6: Luego (hoja 4 y las dos hojas auxiliares) preguntamos cómo mide este modelo sus errores. Con una recta usábamos el error cuadrático; con probabilidades usamos la entropía cruzada binaria, que castiga fuerte a quien estaba muy seguro y se equivocó. Las hojas aux_funcion_logistica y aux_funcion_de_perdida son auxiliares, para mirar la función logística y la función de pérdida con calma, con sus gráficos.
A7: Con el modelo entrenado viene la parte más importante de la clase (hoja 4, a la derecha del umbral, y hojas 5 y 6): cómo evaluamos un clasificador. Empezamos por el acierto simple, pasamos a la matriz de confusión y de ahí a recall (eficacia: de los malos pagadores, cuántos atrapé) y precision (eficiencia: de los que marqué como malos, cuántos lo eran de verdad). Ese par tiene un trade-off que depende del negocio, y cambiar el umbral es la palanca que lo mueve. La hoja 5 muestra todas las métricas como función del umbral y dibuja la curva ROC punto a punto a partir de esa misma tabla, con su área (AUC). La hoja 6 cierra con la pregunta práctica: si sé cuánto cuesta cada tipo de error, ¿cuál es el umbral que conviene?
A8: Dos decisiones de diseño que conviene tener presentes. Uno: la preparación de los datos (convertir categorías en columnas 0/1, escalar las numéricas) no se hace en este Excel, se hace en el notebook que lo acompaña; aquí se muestra el resultado en las hojas 2 y 3, con una tabla que dice qué se hizo con cada columna. Dos: las 1.000 filas están separadas en 700 de training y 300 de testing desde el principio, y todo lo que es aprender (los pesos, las medias y desviaciones para escalar) usa solo training. Testing se toca únicamente para medir.
A9: Lo que no está en este archivo, a propósito: regularización (L1, L2, elastic net), balanceo de clases, remuestreo, validación cruzada e intervalos de confianza. Cada uno tiene su propia planilla o su sección en el notebook, para que este archivo base se pueda leer de corrido.
A10: Colores: celeste son parámetros que se pueden cambiar (umbral, pesos, costos), amarillo son cálculos intermedios, verde son resultados, gris son valores que vienen calculados desde Python (datos, medias, referencia de scikit-learn).

Sheet 1 datos originales
A1: Los 1.000 clientes de german credit, tal como vienen
A2: Los 1.000 clientes tal como vienen en la base pública german credit (Statlog, UCI). Cada fila es un crédito otorgado; la última columna, class, dice si el cliente resultó ser buen pagador (good, 700 casos) o mal pagador (bad, 300 casos). Las 20 columnas anteriores describen al cliente y al crédito en el momento de la solicitud: cuánto pidió, a cuántos meses, cuánto tenía en la cuenta corriente y en ahorros, historial crediticio, edad, vivienda, propósito del crédito y otras.
A3: Nada de esto se toca aquí. La tabla está para que se vea de dónde salen las hojas siguientes y para poder volver a mirar un cliente concreto por su id.
A5: id | B5: checking_status | C5: duration | D5: credit_history | E5: purpose | F5: credit_amount | G5: savings_status | H5: employment | I5: installment_commitment | J5: personal_status | K5: other_parties | L5: residence_since | M5: property_magnitude | N5: age | O5: other_payment_plans | P5: housing | Q5: existing_credits | R5: job | S5: num_dependents | T5: own_telephone | U5: foreign_worker | V5: class
A6: 1 | B6: <0 | C6: 6 | D6: critical/other existing credit | E6: radio/tv | F6: 1169 | G6: no known savings | H6: >=7 | I6: 4 | J6: male single | K6: none | L6: 4 | M6: real estate | N6: 67 | O6: none | P6: own | Q6: 2 | R6: skilled | S6: 1 | T6: yes | U6: yes | V6: good
A7: 2 | B7: 0<=X<200 | C7: 48 | D7: existing paid | E7: radio/tv | F7: 5951 | G7: <100 | H7: 1<=X<4 | I7: 2 | J7: female div/dep/mar | K7: none | L7: 2 | M7: real estate | N7: 22 | O7: none | P7: own | Q7: 1 | R7: skilled | S7: 1 | T7: none | U7: yes | V7: bad
A8: 3 | B8: no checking | C8: 12 | D8: critical/other existing credit | E8: education | F8: 2096 | G8: <100 | H8: 4<=X<7 | I8: 2 | J8: male single | K8: none | L8: 3 | M8: real estate | N8: 49 | O8: none | P8: own | Q8: 1 | R8: unskilled resident | S8: 2 | T8: none | U8: yes | V8: good
A9: 4 | B9: <0 | C9: 42 | D9: existing paid | E9: furniture/equipment | F9: 7882 | G9: <100 | H9: 4<=X<7 | I9: 2 | J9: male single | K9: guarantor | L9: 4 | M9: life insurance | N9: 45 | O9: none | P9: for free | Q9: 1 | R9: skilled | S9: 2 | T9: none | U9: yes | V9: good
A10: 5 | B10: <0 | C10: 24 | D10: delayed previously | E10: new car | F10: 4870 | G10: <100 | H10: 1<=X<4 | I10: 3 | J10: male single | K10: none | L10: 4 | M10: no known property | N10: 53 | O10: none | P10: for free | Q10: 2 | R10: skilled | S10: 2 | T10: none | U10: yes | V10: bad
A11: 6 | B11: no checking | C11: 36 | D11: existing paid | E11: education | F11: 9055 | G11: no known savings | H11: 1<=X<4 | I11: 2 | J11: male single | K11: none | L11: 4 | M11: no known property | N11: 35 | O11: none | P11: for free | Q11: 1 | R11: unskilled resident | S11: 2 | T11: yes | U11: yes | V11: good
A12: 7 | B12: no checking | C12: 24 | D12: existing paid | E12: furniture/equipment | F12: 2835 | G12: 500<=X<1000 | H12: >=7 | I12: 3 | J12: male single | K12: none | L12: 4 | M12: life insurance | N12: 53 | O12: none | P12: own | Q12: 1 | R12: skilled | S12: 1 | T12: none | U12: yes | V12: good
A13: 8 | B13: 0<=X<200 | C13: 36 | D13: existing paid | E13: used car | F13: 6948 | G13: <100 | H13: 1<=X<4 | I13: 2 | J13: male single | K13: none | L13: 2 | M13: car | N13: 35 | O13: none | P13: rent | Q13: 1 | R13: high qualif/self emp/mgmt | S13: 1 | T13: yes | U13: yes | V13: good
A14: 9 | B14: no checking | C14: 12 | D14: existing paid | E14: radio/tv | F14: 3059 | G14: >=1000 | H14: 4<=X<7 | I14: 2 | J14: male div/sep | K14: none | L14: 4 | M14: real estate | N14: 61 | O14: none | P14: own | Q14: 1 | R14: unskilled resident | S14: 1 | T14: none | U14: yes | V14: good
A15: 10 | B15: 0<=X<200 | C15: 30 | D15: critical/other existing credit | E15: new car | F15: 5234 | G15: <100 | H15: unemployed | I15: 4 | J15: male mar/wid | K15: none | L15: 2 | M15: car | N15: 28 | O15: none | P15: own | Q15: 2 | R15: high qualif/self emp/mgmt | S15: 1 | T15: none | U15: yes | V15: bad
A16: 11 | B16: 0<=X<200 | C16: 12 | D16: existing paid | E16: new car | F16: 1295 | G16: <100 | H16: <1 | I16: 3 | J16: female div/dep/mar | K16: none | L16: 1 | M16: car | N16: 25 | O16: none | P16: rent | Q16: 1 | R16: skilled | S16: 1 | T16: none | U16: yes | V16: bad
A17: 12 | B17: <0 | C17: 48 | D17: existing paid | E17: business | F17: 4308 | G17: <100 | H17: <1 | I17: 3 | J17: female div/dep/mar | K17: none | L17: 4 | M17: life insurance | N17: 24 | O17: none | P17: rent | Q17: 1 | R17: skilled | S17: 1 | T17: none | U17: yes | V17: bad
... A1005: 1000 | B1005: 0<=X<200 | C1005: 45 | D1005: critical/other existing credit | E1005: used car | F1005: 4576 | G1005: 100<=X<500 | H1005: unemployed | I1005: 3 | J1005: male single | K1005: none | L1005: 4 | M1005: car | N1005: 27 | O1005: none | P1005: own | Q1005: 1 | R1005: skilled | S1005: 1 | T1005: none | U1005: yes | V1005: good

Sheet 2 transformar y limpiar
A1: Preparación, paso 1: de palabras a columnas 0/1, y la variable objetivo
A2: Primer paso de la preparación: transformar y limpiar. Un modelo lineal solo puede multiplicar números por pesos, así que las columnas con palabras (cuenta corriente, historial, ahorros, vivienda, propósito) se convierten en columnas 0/1, una por categoría, dejando una categoría fuera como base. La variable objetivo pasa a ser y = 1 si el cliente fue mal pagador, que es el evento que queremos detectar. De las 20 columnas originales nos quedamos con 9, elegidas por ser las que un analista de crédito miraría primero; el notebook usa las 20.
A3: La tabla de arriba dice, columna por columna, de dónde sale cada una. La columna conjunto marca qué filas son training (700) y cuáles testing (300); la separación es al azar pero mantiene la proporción de malos pagadores (30%) en los dos grupos. Esta transformación se hizo en Python: en Excel sería una fórmula por celda que no enseña nada nuevo.
A5: columna nueva | B5: columna original | C5: cómo se construye
A6: y | B6: class | C6: 1 si class = bad (mal pagador), 0 si good. Es el evento que queremos detectar.
A7: duracion | B7: duration | C7: meses del crédito, tal cual
A8: monto | B8: credit_amount | C8: monto del crédito en marcos alemanes, tal cual
A9: edad | B9: age | C9: años, tal cual
A10: cuota_pct_ingreso | B10: installment_commitment | C10: tramo de la cuota como porcentaje del ingreso, de 1 (baja) a 4 (alta), tal cual
A11: cta_negativa | B11: checking_status | C11: 1 si la cuenta corriente está en menos de 0 DM
A12: cta_0_200 | B12: checking_status | C12: 1 si tiene entre 0 y 200 DM
A13: cta_sobre_200 | B13: checking_status | C13: 1 si tiene 200 DM o más. Base (las tres en 0): no tiene cuenta corriente
A14: hist_critico | B14: credit_history | C14: 1 si tiene cuenta crítica u otros créditos en otro banco
A15: hist_atrasos | B15: credit_history | C15: 1 si se atrasó en el pasado
A16: hist_sin_creditos | B16: credit_history | C16: 1 si no ha tenido créditos o los pagó todos. Base: créditos vigentes al día
... A24: proposito_muebles | B24: purpose | C24: 1 si es para muebles o equipamiento. Base: otros (negocio, educación, reparaciones, etc.)
A25: conjunto | C25: training (700 filas) o testing (300 filas), al azar con semilla fija, manteniendo el 30% de malos pagadores en cada grupo
A27: La tabla transformada (valores calculados en Python) | F27: Control: | G27: malos pagadores | H27: =SUM(B29:B1028) | I27: training | J27: =COUNTIF(U29:U1028,"training") | K27: malos en training | L27: =COUNTIFS(U29:U1028,"training",B29:B1028,1)
A28: id | B28: y | C28: duracion | D28: monto | E28: edad | F28: cuota_pct_ingreso | G28: cta_negativa | H28: cta_0_200 | I28: cta_sobre_200 | J28: hist_critico | K28: hist_atrasos | L28: hist_sin_creditos | M28: ahorro_100_1000 | N28: ahorro_sobre_1000 | O28: ahorro_desconocido | P28: vivienda_arriendo | Q28: vivienda_gratis | R28: proposito_auto | S28: proposito_radio_tv | T28: proposito_muebles | U28: conjunto
A29: 1 | B29: 0 | C29: 6 | D29: 1169 | E29: 67 | F29: 4 | G29: 1 | H29: 0 | I29: 0 | J29: 1 | K29: 0 | L29: 0 | M29: 0 | N29: 0 | O29: 1 | P29: 0 | Q29: 0 | R29: 0 | S29: 1 | T29: 0 | U29: training
A30: 2 | B30: 1 | C30: 48 | D30: 5951 | E30: 22 | F30: 2 | G30: 0 | H30: 1 | I30: 0 | J30: 0 | K30: 0 | L30: 0 | M30: 0 | N30: 0 | O30: 0 | P30: 0 | Q30: 0 | R30: 0 | S30: 1 | T30: 0 | U30: training
A31: 3 | B31: 0 | C31: 12 | D31: 2096 | E31: 49 | F31: 2 | G31: 0 | H31: 0 | I31: 0 | J31: 1 | K31: 0 | L31: 0 | M31: 0 | N31: 0 | O31: 0 | P31: 0 | Q31: 0 | R31: 0 | S31: 0 | T31: 0 | U31: training
A32: 4 | B32: 0 | C32: 42 | D32: 7882 | E32: 45 | F32: 2 | G32: 1 | H32: 0 | I32: 0 | J32: 0 | K32: 0 | L32: 0 | M32: 0 | N32: 0 | O32: 0 | P32: 0 | Q32: 1 | R32: 0 | S32: 0 | T32: 1 | U32: testing
A33: 5 | B33: 1 | C33: 24 | D33: 4870 | E33: 53 | F33: 3 | G33: 1 | H33: 0 | I33: 0 | J33: 0 | K33: 1 | L33: 0 | M33: 0 | N33: 0 | O33: 0 | P33: 0 | Q33: 1 | R33: 1 | S33: 0 | T33: 0 | U33: training
A34: 6 | B34: 0 | C34: 36 | D34: 9055 | E34: 35 | F34: 2 | G34: 0 | H34: 0 | I34: 0 | J34: 0 | K34: 0 | L34: 0 | M34: 0 | N34: 0 | O34: 1 | P34: 0 | Q34: 1 | R34: 0 | S34: 0 | T34: 0 | U34: testing
A35: 7 | B35: 0 | C35: 24 | D35: 2835 | E35: 53 | F35: 3 | G35: 0 | H35: 0 | I35: 0 | J35: 0 | K35: 0 | L35: 0 | M35: 1 | N35: 0 | O35: 0 | P35: 0 | Q35: 0 | R35: 0 | S35: 0 | T35: 1 | U35: training
A36: 8 | B36: 0 | C36: 36 | D36: 6948 | E36: 35 | F36: 2 | G36: 0 | H36: 1 | I36: 0 | J36: 0 | K36: 0 | L36: 0 | M36: 0 | N36: 0 | O36: 0 | P36: 1 | Q36: 0 | R36: 1 | S36: 0 | T36: 0 | U36: training
A37: 9 | B37: 0 | C37: 12 | D37: 3059 | E37: 61 | F37: 2 | G37: 0 | H37: 0 | I37: 0 | J37: 0 | K37: 0 | L37: 0 | M37: 0 | N37: 1 | O37: 0 | P37: 0 | Q37: 0 | R37: 0 | S37: 1 | T37: 0 | U37: training
A38: 10 | B38: 1 | C38: 30 | D38: 5234 | E38: 28 | F38: 4 | G38: 0 | H38: 1 | I38: 0 | J38: 1 | K38: 0 | L38: 0 | M38: 0 | N38: 0 | O38: 0 | P38: 0 | Q38: 0 | R38: 1 | S38: 0 | T38: 0 | U38: training
A39: 11 | B39: 1 | C39: 12 | D39: 1295 | E39: 25 | F39: 3 | G39: 0 | H39: 1 | I39: 0 | J39: 0 | K39: 0 | L39: 0 | M39: 0 | N39: 0 | O39: 0 | P39: 1 | Q39: 0 | R39: 1 | S39: 0 | T39: 0 | U39: training
A40: 12 | B40: 1 | C40: 48 | D40: 4308 | E40: 24 | F40: 3 | G40: 1 | H40: 0 | I40: 0 | J40: 0 | K40: 0 | L40: 0 | M40: 0 | N40: 0 | O40: 0 | P40: 1 | Q40: 0 | R40: 0 | S40: 0 | T40: 0 | U40: training
... A1028: 1000 | B1028: 0 | C1028: 45 | D1028: 4576 | E1028: 27 | F1028: 3 | G1028: 0 | H1028: 1 | I1028: 0 | J1028: 1 | K1028: 0 | L1028: 0 | M1028: 1 | N1028: 0 | O1028: 0 | P1028: 0 | Q1028: 0 | R1028: 1 | S1028: 0 | T1028: 0 | U1028: training

Sheet 3 escalar
A1: Preparación, paso 2: escalar las numéricas con media y desviación de training
A2: Segundo paso de la preparación: escalar. Las cuatro columnas numéricas tienen unidades muy distintas (meses, marcos alemanes, años, tramos de 1 a 4); si se dejan así, el peso del monto sería minúsculo comparado con el de la cuota, y Solver tendría problemas para moverse. A cada una le restamos su promedio y la dividimos por su desviación estándar, igual que en las clases anteriores. Las columnas 0/1 no se escalan: ya están en una escala comparable y así el peso de cada dummy se lee directo como el efecto de pertenecer a esa categoría.
A3: El detalle que importa: el promedio y la desviación se calculan solo con las 700 filas de training, y con esos mismos números se escalan las 300 de testing. Si usáramos las 1.000, estaríamos dejando que testing influya en el modelo, aunque sea de forma mínima. Es la primera regla de higiene de todo el curso: testing no participa en nada que sea aprender.
A5: columna | B5: promedio (training) | C5: desv. estándar (training) | D5: fórmula de la columna escalada
A6: duracion | B6: =AVERAGEIF('2 transformar y limpiar'!$U$29:$U$1028,"training",'2 transformar y limpiar'!$C$29:$C$1028) | C6: =SQRT(SUMPRODUCT(('2 transformar y limpiar'!$U$29:$U$1028="training")*'2 transformar y limpiar'!$C$29:$C$1028^2)/COUNTIF('2 transformar y limpiar'!$U$29:$U$1028,"training")-B6^2) | D6: (duracion − promedio) / desviación
A7: monto | B7: =AVERAGEIF('2 transformar y limpiar'!$U$29:$U$1028,"training",'2 transformar y limpiar'!$D$29:$D$1028) | C7: =SQRT(SUMPRODUCT(('2 transformar y limpiar'!$U$29:$U$1028="training")*'2 transformar y limpiar'!$D$29:$D$1028^2)/COUNTIF('2 transformar y limpiar'!$U$29:$U$1028,"training")-B7^2) | D7: (monto − promedio) / desviación
A8: edad | B8: =AVERAGEIF('2 transformar y limpiar'!$U$29:$U$1028,"training",'2 transformar y limpiar'!$E$29:$E$1028) | C8: =SQRT(SUMPRODUCT(('2 transformar y limpiar'!$U$29:$U$1028="training")*'2 transformar y limpiar'!$E$29:$E$1028^2)/COUNTIF('2 transformar y limpiar'!$U$29:$U$1028,"training")-B8^2) | D8: (edad − promedio) / desviación
A9: cuota_pct_ingreso | B9: =AVERAGEIF('2 transformar y limpiar'!$U$29:$U$1028,"training",'2 transformar y limpiar'!$F$29:$F$1028) | C9: =SQRT(SUMPRODUCT(('2 transformar y limpiar'!$U$29:$U$1028="training")*'2 transformar y limpiar'!$F$29:$F$1028^2)/COUNTIF('2 transformar y limpiar'!$U$29:$U$1028,"training")-B9^2) | D9: (cuota_pct_ingreso − promedio) / desviación
A11: Las 14 columnas 0/1 no se escalan. Las medias y desviaciones de arriba son fórmulas sobre la hoja 2: cámbiale el conjunto a una fila y verás moverse los números.
A13: La tabla escalada (fórmulas para las numéricas, copia directa para el resto)
A14: id | B14: y | C14: duracion | D14: monto | E14: edad | F14: cuota_pct_ingreso | G14: cta_negativa | H14: cta_0_200 | I14: cta_sobre_200 | J14: hist_critico | K14: hist_atrasos | L14: hist_sin_creditos | M14: ahorro_100_1000 | N14: ahorro_sobre_1000 | O14: ahorro_desconocido | P14: vivienda_arriendo | Q14: vivienda_gratis | R14: proposito_auto | S14: proposito_radio_tv | T14: proposito_muebles | U14: conjunto
A15: ='2 transformar y limpiar'!A29 | B15: ='2 transformar y limpiar'!B29 | C15: =('2 transformar y limpiar'!C29-$B$6)/$C$6 | D15: =('2 transformar y limpiar'!D29-$B$7)/$C$7 | E15: =('2 transformar y limpiar'!E29-$B$8)/$C$8 | F15: =('2 transformar y limpiar'!F29-$B$9)/$C$9 | G15: ='2 transformar y limpiar'!G29 | H15: ='2 transformar y limpiar'!H29 | I15: ='2 transformar y limpiar'!I29 | J15: ='2 transformar y limpiar'!J29 | K15: ='2 transformar y limpiar'!K29 | L15: ='2 transformar y limpiar'!L29 | M15: ='2 transformar y limpiar'!M29 | N15: ='2 transformar y limpiar'!N29 | ... U15: ='2 transformar y limpiar'!U29
A16: ='2 transformar y limpiar'!A30 | B16: ='2 transformar y limpiar'!B30 | C16: =('2 transformar y limpiar'!C30-$B$6)/$C$6 | D16: =('2 transformar y limpiar'!D30-$B$7)/$C$7 | E16: =('2 transformar y limpiar'!E30-$B$8)/$C$8 | F16: =('2 transformar y limpiar'!F30-$B$9)/$C$9 | G16: ='2 transformar y limpiar'!G30 | H16: ='2 transformar y limpiar'!H30 | I16: ='2 transformar y limpiar'!I30 | J16: ='2 transformar y limpiar'!J30 | K16: ='2 transformar y limpiar'!K30 | L16: ='2 transformar y limpiar'!L30 | M16: ='2 transformar y limpiar'!M30 | N16: ='2 transformar y limpiar'!N30 | ... U16: ='2 transformar y limpiar'!U30
A17: ='2 transformar y limpiar'!A31 | B17: ='2 transformar y limpiar'!B31 | C17: =('2 transformar y limpiar'!C31-$B$6)/$C$6 | D17: =('2 transformar y limpiar'!D31-$B$7)/$C$7 | E17: =('2 transformar y limpiar'!E31-$B$8)/$C$8 | F17: =('2 transformar y limpiar'!F31-$B$9)/$C$9 | G17: ='2 transformar y limpiar'!G31 | H17: ='2 transformar y limpiar'!H31 | I17: ='2 transformar y limpiar'!I31 | J17: ='2 transformar y limpiar'!J31 | K17: ='2 transformar y limpiar'!K31 | L17: ='2 transformar y limpiar'!L31 | M17: ='2 transformar y limpiar'!M31 | N17: ='2 transformar y limpiar'!N31 | ... U17: ='2 transformar y limpiar'!U31
A18: ='2 transformar y limpiar'!A32 | B18: ='2 transformar y limpiar'!B32 | C18: =('2 transformar y limpiar'!C32-$B$6)/$C$6 | D18: =('2 transformar y limpiar'!D32-$B$7)/$C$7 | E18: =('2 transformar y limpiar'!E32-$B$8)/$C$8 | F18: =('2 transformar y limpiar'!F32-$B$9)/$C$9 | G18: ='2 transformar y limpiar'!G32 | H18: ='2 transformar y limpiar'!H32 | I18: ='2 transformar y limpiar'!I32 | J18: ='2 transformar y limpiar'!J32 | K18: ='2 transformar y limpiar'!K32 | L18: ='2 transformar y limpiar'!L32 | M18: ='2 transformar y limpiar'!M32 | N18: ='2 transformar y limpiar'!N32 | ... U18: ='2 transformar y limpiar'!U32
A19: ='2 transformar y limpiar'!A33 | B19: ='2 transformar y limpiar'!B33 | C19: =('2 transformar y limpiar'!C33-$B$6)/$C$6 | D19: =('2 transformar y limpiar'!D33-$B$7)/$C$7 | E19: =('2 transformar y limpiar'!E33-$B$8)/$C$8 | F19: =('2 transformar y limpiar'!F33-$B$9)/$C$9 | G19: ='2 transformar y limpiar'!G33 | H19: ='2 transformar y limpiar'!H33 | I19: ='2 transformar y limpiar'!I33 | J19: ='2 transformar y limpiar'!J33 | K19: ='2 transformar y limpiar'!K33 | L19: ='2 transformar y limpiar'!L33 | M19: ='2 transformar y limpiar'!M33 | N19: ='2 transformar y limpiar'!N33 | ... U19: ='2 transformar y limpiar'!U33
A20: ='2 transformar y limpiar'!A34 | B20: ='2 transformar y limpiar'!B34 | C20: =('2 transformar y limpiar'!C34-$B$6)/$C$6 | D20: =('2 transformar y limpiar'!D34-$B$7)/$C$7 | E20: =('2 transformar y limpiar'!E34-$B$8)/$C$8 | F20: =('2 transformar y limpiar'!F34-$B$9)/$C$9 | G20: ='2 transformar y limpiar'!G34 | H20: ='2 transformar y limpiar'!H34 | I20: ='2 transformar y limpiar'!I34 | J20: ='2 transformar y limpiar'!J34 | K20: ='2 transformar y limpiar'!K34 | L20: ='2 transformar y limpiar'!L34 | M20: ='2 transformar y limpiar'!M34 | N20: ='2 transformar y limpiar'!N34 | ... U20: ='2 transformar y limpiar'!U34
A21: ='2 transformar y limpiar'!A35 | B21: ='2 transformar y limpiar'!B35 | C21: =('2 transformar y limpiar'!C35-$B$6)/$C$6 | D21: =('2 transformar y limpiar'!D35-$B$7)/$C$7 | E21: =('2 transformar y limpiar'!E35-$B$8)/$C$8 | F21: =('2 transformar y limpiar'!F35-$B$9)/$C$9 | G21: ='2 transformar y limpiar'!G35 | H21: ='2 transformar y limpiar'!H35 | I21: ='2 transformar y limpiar'!I35 | J21: ='2 transformar y limpiar'!J35 | K21: ='2 transformar y limpiar'!K35 | L21: ='2 transformar y limpiar'!L35 | M21: ='2 transformar y limpiar'!M35 | N21: ='2 transformar y limpiar'!N35 | ... U21: ='2 transformar y limpiar'!U35
A22: ='2 transformar y limpiar'!A36 | B22: ='2 transformar y limpiar'!B36 | C22: =('2 transformar y limpiar'!C36-$B$6)/$C$6 | D22: =('2 transformar y limpiar'!D36-$B$7)/$C$7 | E22: =('2 transformar y limpiar'!E36-$B$8)/$C$8 | F22: =('2 transformar y limpiar'!F36-$B$9)/$C$9 | G22: ='2 transformar y limpiar'!G36 | H22: ='2 transformar y limpiar'!H36 | I22: ='2 transformar y limpiar'!I36 | J22: ='2 transformar y limpiar'!J36 | K22: ='2 transformar y limpiar'!K36 | L22: ='2 transformar y limpiar'!L36 | M22: ='2 transformar y limpiar'!M36 | N22: ='2 transformar y limpiar'!N36 | ... U22: ='2 transformar y limpiar'!U36
A23: ='2 transformar y limpiar'!A37 | B23: ='2 transformar y limpiar'!B37 | C23: =('2 transformar y limpiar'!C37-$B$6)/$C$6 | D23: =('2 transformar y limpiar'!D37-$B$7)/$C$7 | E23: =('2 transformar y limpiar'!E37-$B$8)/$C$8 | F23: =('2 transformar y limpiar'!F37-$B$9)/$C$9 | G23: ='2 transformar y limpiar'!G37 | H23: ='2 transformar y limpiar'!H37 | I23: ='2 transformar y limpiar'!I37 | J23: ='2 transformar y limpiar'!J37 | K23: ='2 transformar y limpiar'!K37 | L23: ='2 transformar y limpiar'!L37 | M23: ='2 transformar y limpiar'!M37 | N23: ='2 transformar y limpiar'!N37 | ... U23: ='2 transformar y limpiar'!U37
A24: ='2 transformar y limpiar'!A38 | B24: ='2 transformar y limpiar'!B38 | C24: =('2 transformar y limpiar'!C38-$B$6)/$C$6 | D24: =('2 transformar y limpiar'!D38-$B$7)/$C$7 | E24: =('2 transformar y limpiar'!E38-$B$8)/$C$8 | F24: =('2 transformar y limpiar'!F38-$B$9)/$C$9 | G24: ='2 transformar y limpiar'!G38 | H24: ='2 transformar y limpiar'!H38 | I24: ='2 transformar y limpiar'!I38 | J24: ='2 transformar y limpiar'!J38 | K24: ='2 transformar y limpiar'!K38 | L24: ='2 transformar y limpiar'!L38 | M24: ='2 transformar y limpiar'!M38 | N24: ='2 transformar y limpiar'!N38 | ... U24: ='2 transformar y limpiar'!U38
A25: ='2 transformar y limpiar'!A39 | B25: ='2 transformar y limpiar'!B39 | C25: =('2 transformar y limpiar'!C39-$B$6)/$C$6 | D25: =('2 transformar y limpiar'!D39-$B$7)/$C$7 | E25: =('2 transformar y limpiar'!E39-$B$8)/$C$8 | F25: =('2 transformar y limpiar'!F39-$B$9)/$C$9 | G25: ='2 transformar y limpiar'!G39 | H25: ='2 transformar y limpiar'!H39 | I25: ='2 transformar y limpiar'!I39 | J25: ='2 transformar y limpiar'!J39 | K25: ='2 transformar y limpiar'!K39 | L25: ='2 transformar y limpiar'!L39 | M25: ='2 transformar y limpiar'!M39 | N25: ='2 transformar y limpiar'!N39 | ... U25: ='2 transformar y limpiar'!U39
A26: ='2 transformar y limpiar'!A40 | B26: ='2 transformar y limpiar'!B40 | C26: =('2 transformar y limpiar'!C40-$B$6)/$C$6 | D26: =('2 transformar y limpiar'!D40-$B$7)/$C$7 | E26: =('2 transformar y limpiar'!E40-$B$8)/$C$8 | F26: =('2 transformar y limpiar'!F40-$B$9)/$C$9 | G26: ='2 transformar y limpiar'!G40 | H26: ='2 transformar y limpiar'!H40 | I26: ='2 transformar y limpiar'!I40 | J26: ='2 transformar y limpiar'!J40 | K26: ='2 transformar y limpiar'!K40 | L26: ='2 transformar y limpiar'!L40 | M26: ='2 transformar y limpiar'!M40 | N26: ='2 transformar y limpiar'!N40 | ... U26: ='2 transformar y limpiar'!U40
... A1014: ='2 transformar y limpiar'!A1028 | B1014: ='2 transformar y limpiar'!B1028 | C1014: =('2 transformar y limpiar'!C1028-$B$6)/$C$6 | D1014: =('2 transformar y limpiar'!D1028-$B$7)/$C$7 | E1014: =('2 transformar y limpiar'!E1028-$B$8)/$C$8 | F1014: =('2 transformar y limpiar'!F1028-$B$9)/$C$9 | G1014: ='2 transformar y limpiar'!G1028 | H1014: ='2 transformar y limpiar'!H1028 | I1014: ='2 transformar y limpiar'!I1028 | J1014: ='2 transformar y limpiar'!J1028 | K1014: ='2 transformar y limpiar'!K1028 | L1014: ='2 transformar y limpiar'!L1028 | M1014: ='2 transformar y limpiar'!M1028 | N1014: ='2 transformar y limpiar'!N1028 | ... U1014: ='2 transformar y limpiar'!U1028

Sheet 4 modelo, umbral y evaluación
A1: El modelo (recta Z, logística p, pérdida, Solver), el umbral y la evaluación
A2: Aquí está el modelo. Cada cliente tiene su fila con las 18 columnas ya escaladas y, a la derecha, un solo bloque de pesos (thetas) que se usa dos veces. La columna ŷ modelo simple es la regresión lineal de las clases anteriores: intercepto más cada columna por su peso, leída directo como predicción de y. Los pesos parten en 0,3 parejo, a propósito: con eso la recta se escapa del rango [0, 1] enseguida, y el bloque bajo la tabla lo muestra con el mínimo y el máximo por conjunto. Ese es el problema de la sección 1 de la clase: una recta no tiene tope, y un número fuera de [0, 1] no se puede leer como probabilidad.
A3: La columna p resuelve eso con los mismos pesos: p = 1 / (1 + exp(−Z)) es la función logística (hoja aux_funcion_logistica), que toma cualquier número y lo lleva a (0, 1). Ahora p sí se lee como la probabilidad de que el cliente sea mal pagador, y la columna predicción la colapsa a 1 o 0 comparándola con el umbral (celda celeste, por ahora 0,5). La columna pérdida es la entropía cruzada de cada fila: −ln(p) si el cliente era malo, −ln(1 − p) si era bueno (hoja aux_funcion_de_perdida). El promedio de esa columna sobre training es la función de costo, y es lo que Solver minimiza moviendo los pesos.
A4: Para usar Solver: objetivo = celda de pérdida total en training (la primera verde, la suma de las 700 filas), cambiando las celdas celestes de los pesos, método GRG no lineal, sin restricciones, y en Opciones bajar la convergencia a 0,000001 con derivadas centrales (el bloque de resultados lo detalla). Debería llegar a la misma pérdida que la referencia de scikit-learn (columna gris) y a pesos casi iguales, porque esta función de costo tiene un solo mínimo. La evaluación de la derecha y las hojas 5 y 6 leen estos pesos, así que antes de Solver muestran el modelo malo y después el entrenado; si quieres saltarte el Solver, copia la columna gris sobre la celeste.
A5: Cómo evaluamos el modelo (bloque de la derecha, junto al umbral). El acierto (accuracy) es el punto de partida: qué fracción de los clientes quedó bien clasificada. Pero esconde lo que importa: en esta base, un modelo que dijera que todos pagan acertaría el 70% sin haber aprendido nada, y no atraparía a ningún mal pagador. La matriz de confusión separa los cuatro casos: verdaderos positivos (era malo y lo marqué), falsos positivos (era bueno y lo marqué), verdaderos negativos y falsos negativos (era malo y lo dejé pasar). Aquí positivo significa mal pagador, porque es el evento que queremos detectar.
A6: De la matriz salen las dos métricas que hay que saber leer. Recall = TP / (TP + FN): de todos los malos pagadores que había, qué fracción atrapé. Es una medida de eficacia. Precision = TP / (TP + FP): de todos los que marqué como malos, qué fracción lo era de verdad. Es una medida de eficiencia, porque cada marca en falso cuesta (un buen cliente rechazado, una llamada de cobranza inútil). F1 es el promedio armónico de las dos, útil como resumen cuando no se sabe cuál importa más. Las tres se muestran para training y para testing; la que cuenta es la de testing.
A7: El trade-off entre eficacia y eficiencia es el corazón de la clase. En riesgo de crédito, dejar pasar a un mal pagador (FN) cuesta el capital prestado, y rechazar a un buen pagador (FP) cuesta el margen que se dejó de ganar: se privilegia recall. En churn, contactar a un cliente que no se iba cuesta poco, pero el presupuesto de retención es finito: precision importa más de lo que parece. En fraude, marcar operaciones legítimas molesta a los clientes honestos: la eficiencia es lo que mantiene la fricción tolerable. La palanca para moverse entre los dos es el umbral, y de eso trata la hoja 5.
AB10: Pesos del modelo (theta): los mismos para la recta y para la logística | AG10: EVALUACIÓN (usa el umbral celeste de la izquierda: muévelo y mira cómo cambian las matrices)
A11: id | B11: conjunto | C11: y | D11: duracion | E11: monto | F11: edad | G11: cuota_pct_ingreso | H11: cta_negativa | I11: cta_0_200 | J11: cta_sobre_200 | K11: hist_critico | L11: hist_atrasos | M11: hist_sin_creditos | N11: ahorro_100_1000 | O11: ahorro_sobre_1000 | P11: ahorro_desconocido | Q11: vivienda_arriendo | R11: vivienda_gratis | S11: proposito_auto | T11: proposito_radio_tv | U11: proposito_muebles | V11: ŷ modelo simple (Z) | W11: p (logística) | X11: pérdida | Y11: predicción | Z11: acierto | AB11: variable | AC11: theta (celeste: cámbialo o deja que Solver lo mueva) | AD11: referencia scikit-learn (la solución)
A12: ='3 escalar'!A15 | B12: ='3 escalar'!U15 | C12: ='3 escalar'!B15 | D12: ='3 escalar'!C15 | E12: ='3 escalar'!D15 | F12: ='3 escalar'!E15 | G12: ='3 escalar'!F15 | H12: ='3 escalar'!G15 | I12: ='3 escalar'!H15 | J12: ='3 escalar'!I15 | ... U12: ='3 escalar'!T15 | V12: =$AC$12+D12*$AC$13+E12*$AC$14+F12*$AC$15+G12*$AC$16+H12*$AC$17+I12*$AC$18+J12*$AC$19+K12*$AC$20+L12*$AC$21+M12*$AC$22+N12*$AC$23+O12*$AC$24+P12*$AC$25+Q12*$AC$26+R12*$AC$27+S12*$AC$28+T12*$AC$29+U12*$AC$30 | W12: =1/(1+EXP(-V12)) | X12: =-IF(C12=1,LN(W12),LN(1-W12)) | Y12: =IF(W12>$AC$32,1,0) | Z12: =IF(Y12=C12,1,0) | AB12: intercepto | AC12: 0.3 | AD12: -1.341271 | AG12: Matriz de confusión, training (700 clientes) | AM12: Matriz de confusión, testing (300 clientes)
A13: ='3 escalar'!A16 | B13: ='3 escalar'!U16 | C13: ='3 escalar'!B16 | D13: ='3 escalar'!C16 | E13: ='3 escalar'!D16 | F13: ='3 escalar'!E16 | G13: ='3 escalar'!F16 | H13: ='3 escalar'!G16 | I13: ='3 escalar'!H16 | J13: ='3 escalar'!I16 | ... U13: ='3 escalar'!T16 | V13: =$AC$12+D13*$AC$13+E13*$AC$14+F13*$AC$15+G13*$AC$16+H13*$AC$17+I13*$AC$18+J13*$AC$19+K13*$AC$20+L13*$AC$21+M13*$AC$22+N13*$AC$23+O13*$AC$24+P13*$AC$25+Q13*$AC$26+R13*$AC$27+S13*$AC$28+T13*$AC$29+U13*$AC$30 | W13: =1/(1+EXP(-V13)) | X13: =-IF(C13=1,LN(W13),LN(1-W13)) | Y13: =IF(W13>$AC$32,1,0) | Z13: =IF(Y13=C13,1,0) | AB13: duracion | AC13: 0.3 | AD13: 0.32470125 | AI13: predicho 0 (paga) | AJ13: predicho 1 (no paga) | AK13: total | AO13: predicho 0 (paga) | AP13: predicho 1 (no paga) | AQ13: total
A14: ='3 escalar'!A17 | B14: ='3 escalar'!U17 | C14: ='3 escalar'!B17 | D14: ='3 escalar'!C17 | E14: ='3 escalar'!D17 | F14: ='3 escalar'!E17 | G14: ='3 escalar'!F17 | H14: ='3 escalar'!G17 | I14: ='3 escalar'!H17 | J14: ='3 escalar'!I17 | ... U14: ='3 escalar'!T17 | V14: =$AC$12+D14*$AC$13+E14*$AC$14+F14*$AC$15+G14*$AC$16+H14*$AC$17+I14*$AC$18+J14*$AC$19+K14*$AC$20+L14*$AC$21+M14*$AC$22+N14*$AC$23+O14*$AC$24+P14*$AC$25+Q14*$AC$26+R14*$AC$27+S14*$AC$28+T14*$AC$29+U14*$AC$30 | W14: =1/(1+EXP(-V14)) | X14: =-IF(C14=1,LN(W14),LN(1-W14)) | Y14: =IF(W14>$AC$32,1,0) | Z14: =IF(Y14=C14,1,0) | AB14: monto | AC14: 0.3 | AD14: 0.11635359 | AG14: real 0 (buen pagador) | AH14: TN | FP | AI14: =COUNTIFS($B$12:$B$1011,"training",$C$12:$C$1011,0,$Y$12:$Y$1011,0) | AJ14: =COUNTIFS($B$12:$B$1011,"training",$C$12:$C$1011,0,$Y$12:$Y$1011,1) | AK14: =AI14+AJ14 | AM14: real 0 (buen pagador) | AN14: TN | FP | AO14: =COUNTIFS($B$12:$B$1011,"testing",$C$12:$C$1011,0,$Y$12:$Y$1011,0) | AP14: =COUNTIFS($B$12:$B$1011,"testing",$C$12:$C$1011,0,$Y$12:$Y$1011,1) | AQ14: =AO14+AP14
A15: ='3 escalar'!A18 | B15: ='3 escalar'!U18 | C15: ='3 escalar'!B18 | D15: ='3 escalar'!C18 | E15: ='3 escalar'!D18 | F15: ='3 escalar'!E18 | G15: ='3 escalar'!F18 | H15: ='3 escalar'!G18 | I15: ='3 escalar'!H18 | J15: ='3 escalar'!I18 | ... U15: ='3 escalar'!T18 | V15: =$AC$12+D15*$AC$13+E15*$AC$14+F15*$AC$15+G15*$AC$16+H15*$AC$17+I15*$AC$18+J15*$AC$19+K15*$AC$20+L15*$AC$21+M15*$AC$22+N15*$AC$23+O15*$AC$24+P15*$AC$25+Q15*$AC$26+R15*$AC$27+S15*$AC$28+T15*$AC$29+U15*$AC$30 | W15: =1/(1+EXP(-V15)) | X15: =-IF(C15=1,LN(W15),LN(1-W15)) | Y15: =IF(W15>$AC$32,1,0) | Z15: =IF(Y15=C15,1,0) | AB15: edad | AC15: 0.3 | AD15: -0.099145225 | AG15: real 1 (mal pagador) | AH15: FN | TP | AI15: =COUNTIFS($B$12:$B$1011,"training",$C$12:$C$1011,1,$Y$12:$Y$1011,0) | AJ15: =COUNTIFS($B$12:$B$1011,"training",$C$12:$C$1011,1,$Y$12:$Y$1011,1) | AK15: =AI15+AJ15 | AM15: real 1 (mal pagador) | AN15: FN | TP | AO15: =COUNTIFS($B$12:$B$1011,"testing",$C$12:$C$1011,1,$Y$12:$Y$1011,0) | AP15: =COUNTIFS($B$12:$B$1011,"testing",$C$12:$C$1011,1,$Y$12:$Y$1011,1) | AQ15: =AO15+AP15
A16: ='3 escalar'!A19 | B16: ='3 escalar'!U19 | C16: ='3 escalar'!B19 | D16: ='3 escalar'!C19 | E16: ='3 escalar'!D19 | F16: ='3 escalar'!E19 | G16: ='3 escalar'!F19 | H16: ='3 escalar'!G19 | I16: ='3 escalar'!H19 | J16: ='3 escalar'!I19 | ... U16: ='3 escalar'!T19 | V16: =$AC$12+D16*$AC$13+E16*$AC$14+F16*$AC$15+G16*$AC$16+H16*$AC$17+I16*$AC$18+J16*$AC$19+K16*$AC$20+L16*$AC$21+M16*$AC$22+N16*$AC$23+O16*$AC$24+P16*$AC$25+Q16*$AC$26+R16*$AC$27+S16*$AC$28+T16*$AC$29+U16*$AC$30 | W16: =1/(1+EXP(-V16)) | X16: =-IF(C16=1,LN(W16),LN(1-W16)) | Y16: =IF(W16>$AC$32,1,0) | Z16: =IF(Y16=C16,1,0) | AB16: cuota_pct_ingreso | AC16: 0.3 | AD16: 0.28721577 | AG16: total | AI16: =AI14+AI15 | AJ16: =AJ14+AJ15 | AK16: =AK14+AK15 | AM16: total | AO16: =AO14+AO15 | AP16: =AP14+AP15 | AQ16: =AQ14+AQ15
A17: ='3 escalar'!A20 | B17: ='3 escalar'!U20 | C17: ='3 escalar'!B20 | D17: ='3 escalar'!C20 | E17: ='3 escalar'!D20 | F17: ='3 escalar'!E20 | G17: ='3 escalar'!F20 | H17: ='3 escalar'!G20 | I17: ='3 escalar'!H20 | J17: ='3 escalar'!I20 | ... U17: ='3 escalar'!T20 | V17: =$AC$12+D17*$AC$13+E17*$AC$14+F17*$AC$15+G17*$AC$16+H17*$AC$17+I17*$AC$18+J17*$AC$19+K17*$AC$20+L17*$AC$21+M17*$AC$22+N17*$AC$23+O17*$AC$24+P17*$AC$25+Q17*$AC$26+R17*$AC$27+S17*$AC$28+T17*$AC$29+U17*$AC$30 | W17: =1/(1+EXP(-V17)) | X17: =-IF(C17=1,LN(W17),LN(1-W17)) | Y17: =IF(W17>$AC$32,1,0) | Z17: =IF(Y17=C17,1,0) | AB17: cta_negativa | AC17: 0.3 | AD17: 1.5464027
A18: ='3 escalar'!A21 | B18: ='3 escalar'!U21 | C18: ='3 escalar'!B21 | D18: ='3 escalar'!C21 | E18: ='3 escalar'!D21 | F18: ='3 escalar'!E21 | G18: ='3 escalar'!F21 | H18: ='3 escalar'!G21 | I18: ='3 escalar'!H21 | J18: ='3 escalar'!I21 | ... U18: ='3 escalar'!T21 | V18: =$AC$12+D18*$AC$13+E18*$AC$14+F18*$AC$15+G18*$AC$16+H18*$AC$17+I18*$AC$18+J18*$AC$19+K18*$AC$20+L18*$AC$21+M18*$AC$22+N18*$AC$23+O18*$AC$24+P18*$AC$25+Q18*$AC$26+R18*$AC$27+S18*$AC$28+T18*$AC$29+U18*$AC$30 | W18: =1/(1+EXP(-V18)) | X18: =-IF(C18=1,LN(W18),LN(1-W18)) | Y18: =IF(W18>$AC$32,1,0) | Z18: =IF(Y18=C18,1,0) | AB18: cta_0_200 | AC18: 0.3 | AD18: 1.2949978 | AG18: Reporte de clasificación (como classification_report de scikit-learn) | AM18: Reporte de clasificación (como classification_report de scikit-learn)
A19: ='3 escalar'!A22 | B19: ='3 escalar'!U22 | C19: ='3 escalar'!B22 | D19: ='3 escalar'!C22 | E19: ='3 escalar'!D22 | F19: ='3 escalar'!E22 | G19: ='3 escalar'!F22 | H19: ='3 escalar'!G22 | I19: ='3 escalar'!H22 | J19: ='3 escalar'!I22 | ... U19: ='3 escalar'!T22 | V19: =$AC$12+D19*$AC$13+E19*$AC$14+F19*$AC$15+G19*$AC$16+H19*$AC$17+I19*$AC$18+J19*$AC$19+K19*$AC$20+L19*$AC$21+M19*$AC$22+N19*$AC$23+O19*$AC$24+P19*$AC$25+Q19*$AC$26+R19*$AC$27+S19*$AC$28+T19*$AC$29+U19*$AC$30 | W19: =1/(1+EXP(-V19)) | X19: =-IF(C19=1,LN(W19),LN(1-W19)) | Y19: =IF(W19>$AC$32,1,0) | Z19: =IF(Y19=C19,1,0) | AB19: cta_sobre_200 | AC19: 0.3 | AD19: 0.66836159 | AH19: precision | AI19: recall | AJ19: f1-score | AK19: support | AN19: precision | AO19: recall | AP19: f1-score | AQ19: support
A20: ='3 escalar'!A23 | B20: ='3 escalar'!U23 | C20: ='3 escalar'!B23 | D20: ='3 escalar'!C23 | E20: ='3 escalar'!D23 | F20: ='3 escalar'!E23 | G20: ='3 escalar'!F23 | H20: ='3 escalar'!G23 | I20: ='3 escalar'!H23 | J20: ='3 escalar'!I23 | ... U20: ='3 escalar'!T23 | V20: =$AC$12+D20*$AC$13+E20*$AC$14+F20*$AC$15+G20*$AC$16+H20*$AC$17+I20*$AC$18+J20*$AC$19+K20*$AC$20+L20*$AC$21+M20*$AC$22+N20*$AC$23+O20*$AC$24+P20*$AC$25+Q20*$AC$26+R20*$AC$27+S20*$AC$28+T20*$AC$29+U20*$AC$30 | W20: =1/(1+EXP(-V20)) | X20: =-IF(C20=1,LN(W20),LN(1-W20)) | Y20: =IF(W20>$AC$32,1,0) | Z20: =IF(Y20=C20,1,0) | AB20: hist_critico | AC20: 0.3 | AD20: -0.65734494 | AG20: clase 0 (paga) | AH20: =IF(AI14+AI15=0,0,AI14/(AI14+AI15)) | AI20: =IF(AI14+AJ14=0,0,AI14/(AI14+AJ14)) | AJ20: =IF(AH20+AI20=0,0,2*AH20*AI20/(AH20+AI20)) | AK20: =AK14 | AM20: clase 0 (paga) | AN20: =IF(AO14+AO15=0,0,AO14/(AO14+AO15)) | AO20: =IF(AO14+AP14=0,0,AO14/(AO14+AP14)) | AP20: =IF(AN20+AO20=0,0,2*AN20*AO20/(AN20+AO20)) | AQ20: =AQ14
A21: ='3 escalar'!A24 | B21: ='3 escalar'!U24 | C21: ='3 escalar'!B24 | D21: ='3 escalar'!C24 | E21: ='3 escalar'!D24 | F21: ='3 escalar'!E24 | G21: ='3 escalar'!F24 | H21: ='3 escalar'!G24 | I21: ='3 escalar'!H24 | J21: ='3 escalar'!I24 | ... U21: ='3 escalar'!T24 | V21: =$AC$12+D21*$AC$13+E21*$AC$14+F21*$AC$15+G21*$AC$16+H21*$AC$17+I21*$AC$18+J21*$AC$19+K21*$AC$20+L21*$AC$21+M21*$AC$22+N21*$AC$23+O21*$AC$24+P21*$AC$25+Q21*$AC$26+R21*$AC$27+S21*$AC$28+T21*$AC$29+U21*$AC$30 | W21: =1/(1+EXP(-V21)) | X21: =-IF(C21=1,LN(W21),LN(1-W21)) | Y21: =IF(W21>$AC$32,1,0) | Z21: =IF(Y21=C21,1,0) | AB21: hist_atrasos | AC21: 0.3 | AD21: -0.040195519 | AG21: clase 1 (no paga) | AH21: =IF(AJ15+AJ14=0,0,AJ15/(AJ15+AJ14)) | AI21: =IF(AJ15+AI15=0,0,AJ15/(AJ15+AI15)) | AJ21: =IF(AH21+AI21=0,0,2*AH21*AI21/(AH21+AI21)) | AK21: =AK15 | AM21: clase 1 (no paga) | AN21: =IF(AP15+AP14=0,0,AP15/(AP15+AP14)) | AO21: =IF(AP15+AO15=0,0,AP15/(AP15+AO15)) | AP21: =IF(AN21+AO21=0,0,2*AN21*AO21/(AN21+AO21)) | AQ21: =AQ15
A22: ='3 escalar'!A25 | B22: ='3 escalar'!U25 | C22: ='3 escalar'!B25 | D22: ='3 escalar'!C25 | E22: ='3 escalar'!D25 | F22: ='3 escalar'!E25 | G22: ='3 escalar'!F25 | H22: ='3 escalar'!G25 | I22: ='3 escalar'!H25 | J22: ='3 escalar'!I25 | ... U22: ='3 escalar'!T25 | V22: =$AC$12+D22*$AC$13+E22*$AC$14+F22*$AC$15+G22*$AC$16+H22*$AC$17+I22*$AC$18+J22*$AC$19+K22*$AC$20+L22*$AC$21+M22*$AC$22+N22*$AC$23+O22*$AC$24+P22*$AC$25+Q22*$AC$26+R22*$AC$27+S22*$AC$28+T22*$AC$29+U22*$AC$30 | W22: =1/(1+EXP(-V22)) | X22: =-IF(C22=1,LN(W22),LN(1-W22)) | Y22: =IF(W22>$AC$32,1,0) | Z22: =IF(Y22=C22,1,0) | AB22: hist_sin_creditos | AC22: 0.3 | AD22: 0.66906563
A23: ='3 escalar'!A26 | B23: ='3 escalar'!U26 | C23: ='3 escalar'!B26 | D23: ='3 escalar'!C26 | E23: ='3 escalar'!D26 | F23: ='3 escalar'!E26 | G23: ='3 escalar'!F26 | H23: ='3 escalar'!G26 | I23: ='3 escalar'!H26 | J23: ='3 escalar'!I26 | ... U23: ='3 escalar'!T26 | V23: =$AC$12+D23*$AC$13+E23*$AC$14+F23*$AC$15+G23*$AC$16+H23*$AC$17+I23*$AC$18+J23*$AC$19+K23*$AC$20+L23*$AC$21+M23*$AC$22+N23*$AC$23+O23*$AC$24+P23*$AC$25+Q23*$AC$26+R23*$AC$27+S23*$AC$28+T23*$AC$29+U23*$AC$30 | W23: =1/(1+EXP(-V23)) | X23: =-IF(C23=1,LN(W23),LN(1-W23)) | Y23: =IF(W23>$AC$32,1,0) | Z23: =IF(Y23=C23,1,0) | AB23: ahorro_100_1000 | AC23: 0.3 | AD23: -0.38958343 | AG23: accuracy | AJ23: =(AJ15+AI14)/AK16 | AK23: =AK16 | AM23: accuracy | AP23: =(AP15+AO14)/AQ16 | AQ23: =AQ16
A24: ='3 escalar'!A27 | B24: ='3 escalar'!U27 | C24: ='3 escalar'!B27 | D24: ='3 escalar'!C27 | E24: ='3 escalar'!D27 | F24: ='3 escalar'!E27 | G24: ='3 escalar'!F27 | H24: ='3 escalar'!G27 | I24: ='3 escalar'!H27 | J24: ='3 escalar'!I27 | ... U24: ='3 escalar'!T27 | V24: =$AC$12+D24*$AC$13+E24*$AC$14+F24*$AC$15+G24*$AC$16+H24*$AC$17+I24*$AC$18+J24*$AC$19+K24*$AC$20+L24*$AC$21+M24*$AC$22+N24*$AC$23+O24*$AC$24+P24*$AC$25+Q24*$AC$26+R24*$AC$27+S24*$AC$28+T24*$AC$29+U24*$AC$30 | W24: =1/(1+EXP(-V24)) | X24: =-IF(C24=1,LN(W24),LN(1-W24)) | Y24: =IF(W24>$AC$32,1,0) | Z24: =IF(Y24=C24,1,0) | AB24: ahorro_sobre_1000 | AC24: 0.3 | AD24: -0.88922386 | AG24: macro avg | AH24: =AVERAGE(AH20,AH21) | AI24: =AVERAGE(AI20,AI21) | AJ24: =AVERAGE(AJ20,AJ21) | AK24: =AK16 | AM24: macro avg | AN24: =AVERAGE(AN20,AN21) | AO24: =AVERAGE(AO20,AO21) | AP24: =AVERAGE(AP20,AP21) | AQ24: =AQ16
A25: ='3 escalar'!A28 | B25: ='3 escalar'!U28 | C25: ='3 escalar'!B28 | D25: ='3 escalar'!C28 | E25: ='3 escalar'!D28 | F25: ='3 escalar'!E28 | G25: ='3 escalar'!F28 | H25: ='3 escalar'!G28 | I25: ='3 escalar'!H28 | J25: ='3 escalar'!I28 | ... U25: ='3 escalar'!T28 | V25: =$AC$12+D25*$AC$13+E25*$AC$14+F25*$AC$15+G25*$AC$16+H25*$AC$17+I25*$AC$18+J25*$AC$19+K25*$AC$20+L25*$AC$21+M25*$AC$22+N25*$AC$23+O25*$AC$24+P25*$AC$25+Q25*$AC$26+R25*$AC$27+S25*$AC$28+T25*$AC$29+U25*$AC$30 | W25: =1/(1+EXP(-V25)) | X25: =-IF(C25=1,LN(W25),LN(1-W25)) | Y25: =IF(W25>$AC$32,1,0) | Z25: =IF(Y25=C25,1,0) | AB25: ahorro_desconocido | AC25: 0.3 | AD25: -1.0760929 | AG25: weighted avg | AH25: =(AH20*AK20+AH21*AK21)/(AK20+AK21) | AI25: =(AI20*AK20+AI21*AK21)/(AK20+AK21) | AJ25: =(AJ20*AK20+AJ21*AK21)/(AK20+AK21) | AK25: =AK16 | AM25: weighted avg | AN25: =(AN20*AQ20+AN21*AQ21)/(AQ20+AQ21) | AO25: =(AO20*AQ20+AO21*AQ21)/(AQ20+AQ21) | AP25: =(AP20*AQ20+AP21*AQ21)/(AQ20+AQ21) | AQ25: =AQ16
A26: ='3 escalar'!A29 | B26: ='3 escalar'!U29 | C26: ='3 escalar'!B29 | D26: ='3 escalar'!C29 | E26: ='3 escalar'!D29 | F26: ='3 escalar'!E29 | G26: ='3 escalar'!F29 | H26: ='3 escalar'!G29 | I26: ='3 escalar'!H29 | J26: ='3 escalar'!I29 | ... U26: ='3 escalar'!T29 | V26: =$AC$12+D26*$AC$13+E26*$AC$14+F26*$AC$15+G26*$AC$16+H26*$AC$17+I26*$AC$18+J26*$AC$19+K26*$AC$20+L26*$AC$21+M26*$AC$22+N26*$AC$23+O26*$AC$24+P26*$AC$25+Q26*$AC$26+R26*$AC$27+S26*$AC$28+T26*$AC$29+U26*$AC$30 | W26: =1/(1+EXP(-V26)) | X26: =-IF(C26=1,LN(W26),LN(1-W26)) | Y26: =IF(W26>$AC$32,1,0) | Z26: =IF(Y26=C26,1,0) | AB26: vivienda_arriendo | AC26: 0.3 | AD26: 0.65383718
A27: ='3 escalar'!A30 | B27: ='3 escalar'!U30 | C27: ='3 escalar'!B30 | D27: ='3 escalar'!C30 | E27: ='3 escalar'!D30 | F27: ='3 escalar'!E30 | G27: ='3 escalar'!F30 | H27: ='3 escalar'!G30 | I27: ='3 escalar'!H30 | J27: ='3 escalar'!I30 | ... U27: ='3 escalar'!T30 | V27: =$AC$12+D27*$AC$13+E27*$AC$14+F27*$AC$15+G27*$AC$16+H27*$AC$17+I27*$AC$18+J27*$AC$19+K27*$AC$20+L27*$AC$21+M27*$AC$22+N27*$AC$23+O27*$AC$24+P27*$AC$25+Q27*$AC$26+R27*$AC$27+S27*$AC$28+T27*$AC$29+U27*$AC$30 | W27: =1/(1+EXP(-V27)) | X27: =-IF(C27=1,LN(W27),LN(1-W27)) | Y27: =IF(W27>$AC$32,1,0) | Z27: =IF(Y27=C27,1,0) | AB27: vivienda_gratis | AC27: 0.3 | AD27: 0.19536536 | AG27: acierto del modelo 'todos pagan' = buenos / total | AH27: =AK14/AK16 | AM27: acierto del modelo 'todos pagan' = buenos / total | AN27: =AQ14/AQ16
A28: ='3 escalar'!A31 | B28: ='3 escalar'!U31 | C28: ='3 escalar'!B31 | D28: ='3 escalar'!C31 | E28: ='3 escalar'!D31 | F28: ='3 escalar'!E31 | G28: ='3 escalar'!F31 | H28: ='3 escalar'!G31 | I28: ='3 escalar'!H31 | J28: ='3 escalar'!I31 | ... U28: ='3 escalar'!T31 | V28: =$AC$12+D28*$AC$13+E28*$AC$14+F28*$AC$15+G28*$AC$16+H28*$AC$17+I28*$AC$18+J28*$AC$19+K28*$AC$20+L28*$AC$21+M28*$AC$22+N28*$AC$23+O28*$AC$24+P28*$AC$25+Q28*$AC$26+R28*$AC$27+S28*$AC$28+T28*$AC$29+U28*$AC$30 | W28: =1/(1+EXP(-V28)) | X28: =-IF(C28=1,LN(W28),LN(1-W28)) | Y28: =IF(W28>$AC$32,1,0) | Z28: =IF(Y28=C28,1,0) | AB28: proposito_auto | AC28: 0.3 | AD28: -0.080165476 | AG28: tasa de falsos positivos = FP / (FP + TN) | AH28: =IF(AJ14+AI14=0,0,AJ14/(AJ14+AI14)) | AM28: tasa de falsos positivos = FP / (FP + TN) | AN28: =IF(AP14+AO14=0,0,AP14/(AP14+AO14))
A29: ='3 escalar'!A32 | B29: ='3 escalar'!U32 | C29: ='3 escalar'!B32 | D29: ='3 escalar'!C32 | E29: ='3 escalar'!D32 | F29: ='3 escalar'!E32 | G29: ='3 escalar'!F32 | H29: ='3 escalar'!G32 | I29: ='3 escalar'!H32 | J29: ='3 escalar'!I32 | ... U29: ='3 escalar'!T32 | V29: =$AC$12+D29*$AC$13+E29*$AC$14+F29*$AC$15+G29*$AC$16+H29*$AC$17+I29*$AC$18+J29*$AC$19+K29*$AC$20+L29*$AC$21+M29*$AC$22+N29*$AC$23+O29*$AC$24+P29*$AC$25+Q29*$AC$26+R29*$AC$27+S29*$AC$28+T29*$AC$29+U29*$AC$30 | W29: =1/(1+EXP(-V29)) | X29: =-IF(C29=1,LN(W29),LN(1-W29)) | Y29: =IF(W29>$AC$32,1,0) | Z29: =IF(Y29=C29,1,0) | AB29: proposito_radio_tv | AC29: 0.3 | AD29: -0.52021065 | AG29: El umbral que usan estas matrices es la celda celeste de la izquierda. Cámbialo y mira cómo se mueven recall y precision en direcciones opuestas.
A30: ='3 escalar'!A33 | B30: ='3 escalar'!U33 | C30: ='3 escalar'!B33 | D30: ='3 escalar'!C33 | E30: ='3 escalar'!D33 | F30: ='3 escalar'!E33 | G30: ='3 escalar'!F33 | H30: ='3 escalar'!G33 | I30: ='3 escalar'!H33 | J30: ='3 escalar'!I33 | ... U30: ='3 escalar'!T33 | V30: =$AC$12+D30*$AC$13+E30*$AC$14+F30*$AC$15+G30*$AC$16+H30*$AC$17+I30*$AC$18+J30*$AC$19+K30*$AC$20+L30*$AC$21+M30*$AC$22+N30*$AC$23+O30*$AC$24+P30*$AC$25+Q30*$AC$26+R30*$AC$27+S30*$AC$28+T30*$AC$29+U30*$AC$30 | W30: =1/(1+EXP(-V30)) | X30: =-IF(C30=1,LN(W30),LN(1-W30)) | Y30: =IF(W30>$AC$32,1,0) | Z30: =IF(Y30=C30,1,0) | AB30: proposito_muebles | AC30: 0.3 | AD30: -0.28180274
A31: ='3 escalar'!A34 | B31: ='3 escalar'!U34 | C31: ='3 escalar'!B34 | D31: ='3 escalar'!C34 | E31: ='3 escalar'!D34 | F31: ='3 escalar'!E34 | G31: ='3 escalar'!F34 | H31: ='3 escalar'!G34 | I31: ='3 escalar'!H34 | J31: ='3 escalar'!I34 | ... U31: ='3 escalar'!T34 | V31: =$AC$12+D31*$AC$13+E31*$AC$14+F31*$AC$15+G31*$AC$16+H31*$AC$17+I31*$AC$18+J31*$AC$19+K31*$AC$20+L31*$AC$21+M31*$AC$22+N31*$AC$23+O31*$AC$24+P31*$AC$25+Q31*$AC$26+R31*$AC$27+S31*$AC$28+T31*$AC$29+U31*$AC$30 | W31: =1/(1+EXP(-V31)) | X31: =-IF(C31=1,LN(W31),LN(1-W31)) | Y31: =IF(W31>$AC$32,1,0) | Z31: =IF(Y31=C31,1,0) | AG31: Referencia scikit-learn en testing con umbral 0,5 y los pesos de la solución:
A32: ='3 escalar'!A35 | B32: ='3 escalar'!U35 | C32: ='3 escalar'!B35 | D32: ='3 escalar'!C35 | E32: ='3 escalar'!D35 | F32: ='3 escalar'!E35 | G32: ='3 escalar'!F35 | H32: ='3 escalar'!G35 | I32: ='3 escalar'!H35 | J32: ='3 escalar'!I35 | ... U32: ='3 escalar'!T35 | V32: =$AC$12+D32*$AC$13+E32*$AC$14+F32*$AC$15+G32*$AC$16+H32*$AC$17+I32*$AC$18+J32*$AC$19+K32*$AC$20+L32*$AC$21+M32*$AC$22+N32*$AC$23+O32*$AC$24+P32*$AC$25+Q32*$AC$26+R32*$AC$27+S32*$AC$28+T32*$AC$29+U32*$AC$30 | W32: =1/(1+EXP(-V32)) | X32: =-IF(C32=1,LN(W32),LN(1-W32)) | Y32: =IF(W32>$AC$32,1,0) | Z32: =IF(Y32=C32,1,0) | AB32: umbral | AC32: 0.5 | AG32: acierto | AH32: 0.78
A33: ='3 escalar'!A36 | B33: ='3 escalar'!U36 | C33: ='3 escalar'!B36 | D33: ='3 escalar'!C36 | E33: ='3 escalar'!D36 | F33: ='3 escalar'!E36 | G33: ='3 escalar'!F36 | H33: ='3 escalar'!G36 | I33: ='3 escalar'!H36 | J33: ='3 escalar'!I36 | ... U33: ='3 escalar'!T36 | V33: =$AC$12+D33*$AC$13+E33*$AC$14+F33*$AC$15+G33*$AC$16+H33*$AC$17+I33*$AC$18+J33*$AC$19+K33*$AC$20+L33*$AC$21+M33*$AC$22+N33*$AC$23+O33*$AC$24+P33*$AC$25+Q33*$AC$26+R33*$AC$27+S33*$AC$28+T33*$AC$29+U33*$AC$30 | W33: =1/(1+EXP(-V33)) | X33: =-IF(C33=1,LN(W33),LN(1-W33)) | Y33: =IF(W33>$AC$32,1,0) | Z33: =IF(Y33=C33,1,0) | AG33: recall | AH33: 0.56666667
A34: ='3 escalar'!A37 | B34: ='3 escalar'!U37 | C34: ='3 escalar'!B37 | D34: ='3 escalar'!C37 | E34: ='3 escalar'!D37 | F34: ='3 escalar'!E37 | G34: ='3 escalar'!F37 | H34: ='3 escalar'!G37 | I34: ='3 escalar'!H37 | J34: ='3 escalar'!I37 | ... U34: ='3 escalar'!T37 | V34: =$AC$12+D34*$AC$13+E34*$AC$14+F34*$AC$15+G34*$AC$16+H34*$AC$17+I34*$AC$18+J34*$AC$19+K34*$AC$20+L34*$AC$21+M34*$AC$22+N34*$AC$23+O34*$AC$24+P34*$AC$25+Q34*$AC$26+R34*$AC$27+S34*$AC$28+T34*$AC$29+U34*$AC$30 | W34: =1/(1+EXP(-V34)) | X34: =-IF(C34=1,LN(W34),LN(1-W34)) | Y34: =IF(W34>$AC$32,1,0) | Z34: =IF(Y34=C34,1,0) | AB34: RESULTADOS | AG34: precision | AH34: 0.65384615
A35: ='3 escalar'!A38 | B35: ='3 escalar'!U38 | C35: ='3 escalar'!B38 | D35: ='3 escalar'!C38 | E35: ='3 escalar'!D38 | F35: ='3 escalar'!E38 | G35: ='3 escalar'!F38 | H35: ='3 escalar'!G38 | I35: ='3 escalar'!H38 | J35: ='3 escalar'!I38 | ... U35: ='3 escalar'!T38 | V35: =$AC$12+D35*$AC$13+E35*$AC$14+F35*$AC$15+G35*$AC$16+H35*$AC$17+I35*$AC$18+J35*$AC$19+K35*$AC$20+L35*$AC$21+M35*$AC$22+N35*$AC$23+O35*$AC$24+P35*$AC$25+Q35*$AC$26+R35*$AC$27+S35*$AC$28+T35*$AC$29+U35*$AC$30 | W35: =1/(1+EXP(-V35)) | X35: =-IF(C35=1,LN(W35),LN(1-W35)) | Y35: =IF(W35>$AC$32,1,0) | Z35: =IF(Y35=C35,1,0) | AB35: pérdida total training, suma de las 700 filas (objetivo de Solver) | AC35: =SUMPRODUCT(($B$12:$B$1011="training")*$X$12:$X$1011) | AG35: F1 | AH35: 0.60714286
A36: ='3 escalar'!A39 | B36: ='3 escalar'!U39 | C36: ='3 escalar'!B39 | D36: ='3 escalar'!C39 | E36: ='3 escalar'!D39 | F36: ='3 escalar'!E39 | G36: ='3 escalar'!F39 | H36: ='3 escalar'!G39 | I36: ='3 escalar'!H39 | J36: ='3 escalar'!I39 | ... U36: ='3 escalar'!T39 | V36: =$AC$12+D36*$AC$13+E36*$AC$14+F36*$AC$15+G36*$AC$16+H36*$AC$17+I36*$AC$18+J36*$AC$19+K36*$AC$20+L36*$AC$21+M36*$AC$22+N36*$AC$23+O36*$AC$24+P36*$AC$25+Q36*$AC$26+R36*$AC$27+S36*$AC$28+T36*$AC$29+U36*$AC$30 | W36: =1/(1+EXP(-V36)) | X36: =-IF(C36=1,LN(W36),LN(1-W36)) | Y36: =IF(W36>$AC$32,1,0) | Z36: =IF(Y36=C36,1,0) | AB36: pérdida promedio training | AC36: =SUMPRODUCT(($B$12:$B$1011="training")*$X$12:$X$1011)/COUNTIF($B$12:$B$1011,"training")
A37: ='3 escalar'!A40 | B37: ='3 escalar'!U40 | C37: ='3 escalar'!B40 | D37: ='3 escalar'!C40 | E37: ='3 escalar'!D40 | F37: ='3 escalar'!E40 | G37: ='3 escalar'!F40 | H37: ='3 escalar'!G40 | I37: ='3 escalar'!H40 | J37: ='3 escalar'!I40 | ... U37: ='3 escalar'!T40 | V37: =$AC$12+D37*$AC$13+E37*$AC$14+F37*$AC$15+G37*$AC$16+H37*$AC$17+I37*$AC$18+J37*$AC$19+K37*$AC$20+L37*$AC$21+M37*$AC$22+N37*$AC$23+O37*$AC$24+P37*$AC$25+Q37*$AC$26+R37*$AC$27+S37*$AC$28+T37*$AC$29+U37*$AC$30 | W37: =1/(1+EXP(-V37)) | X37: =-IF(C37=1,LN(W37),LN(1-W37)) | Y37: =IF(W37>$AC$32,1,0) | Z37: =IF(Y37=C37,1,0) | AB37: pérdida promedio testing | AC37: =SUMPRODUCT(($B$12:$B$1011="testing")*$X$12:$X$1011)/COUNTIF($B$12:$B$1011,"testing")
A38: ='3 escalar'!A41 | B38: ='3 escalar'!U41 | C38: ='3 escalar'!B41 | D38: ='3 escalar'!C41 | E38: ='3 escalar'!D41 | F38: ='3 escalar'!E41 | G38: ='3 escalar'!F41 | H38: ='3 escalar'!G41 | I38: ='3 escalar'!H41 | J38: ='3 escalar'!I41 | ... U38: ='3 escalar'!T41 | V38: =$AC$12+D38*$AC$13+E38*$AC$14+F38*$AC$15+G38*$AC$16+H38*$AC$17+I38*$AC$18+J38*$AC$19+K38*$AC$20+L38*$AC$21+M38*$AC$22+N38*$AC$23+O38*$AC$24+P38*$AC$25+Q38*$AC$26+R38*$AC$27+S38*$AC$28+T38*$AC$29+U38*$AC$30 | W38: =1/(1+EXP(-V38)) | X38: =-IF(C38=1,LN(W38),LN(1-W38)) | Y38: =IF(W38>$AC$32,1,0) | Z38: =IF(Y38=C38,1,0) | AB38: acierto training | AC38: =SUMPRODUCT(($B$12:$B$1011="training")*$Z$12:$Z$1011)/COUNTIF($B$12:$B$1011,"training") | AG38: El trade-off según el negocio
A39: ='3 escalar'!A42 | B39: ='3 escalar'!U42 | C39: ='3 escalar'!B42 | D39: ='3 escalar'!C42 | E39: ='3 escalar'!D42 | F39: ='3 escalar'!E42 | G39: ='3 escalar'!F42 | H39: ='3 escalar'!G42 | I39: ='3 escalar'!H42 | J39: ='3 escalar'!I42 | ... U39: ='3 escalar'!T42 | V39: =$AC$12+D39*$AC$13+E39*$AC$14+F39*$AC$15+G39*$AC$16+H39*$AC$17+I39*$AC$18+J39*$AC$19+K39*$AC$20+L39*$AC$21+M39*$AC$22+N39*$AC$23+O39*$AC$24+P39*$AC$25+Q39*$AC$26+R39*$AC$27+S39*$AC$28+T39*$AC$29+U39*$AC$30 | W39: =1/(1+EXP(-V39)) | X39: =-IF(C39=1,LN(W39),LN(1-W39)) | Y39: =IF(W39>$AC$32,1,0) | Z39: =IF(Y39=C39,1,0) | AB39: acierto testing | AC39: =SUMPRODUCT(($B$12:$B$1011="testing")*$Z$12:$Z$1011)/COUNTIF($B$12:$B$1011,"testing") | AG39: caso | AH39: qué cuesta un falso negativo (no marcar) | AI39: qué cuesta un falso positivo (marcar de más) | AJ39: qué se privilegia
A40: ='3 escalar'!A43 | B40: ='3 escalar'!U43 | C40: ='3 escalar'!B43 | D40: ='3 escalar'!C43 | E40: ='3 escalar'!D43 | F40: ='3 escalar'!E43 | G40: ='3 escalar'!F43 | H40: ='3 escalar'!G43 | I40: ='3 escalar'!H43 | J40: ='3 escalar'!I43 | ... U40: ='3 escalar'!T43 | V40: =$AC$12+D40*$AC$13+E40*$AC$14+F40*$AC$15+G40*$AC$16+H40*$AC$17+I40*$AC$18+J40*$AC$19+K40*$AC$20+L40*$AC$21+M40*$AC$22+N40*$AC$23+O40*$AC$24+P40*$AC$25+Q40*$AC$26+R40*$AC$27+S40*$AC$28+T40*$AC$29+U40*$AC$30 | W40: =1/(1+EXP(-V40)) | X40: =-IF(C40=1,LN(W40),LN(1-W40)) | Y40: =IF(W40>$AC$32,1,0) | Z40: =IF(Y40=C40,1,0) | AB40: referencia scikit-learn: pérdida total training | AC40: 350.25914 | AG40: riesgo de crédito | AH40: aprobar a quien no paga: se pierde el capital | AI40: rechazar a quien pagaba: se pierde el margen | AJ40: recall (eficacia), con el costo asimétrico de la hoja 6
A41: ='3 escalar'!A44 | B41: ='3 escalar'!U44 | C41: ='3 escalar'!B44 | D41: ='3 escalar'!C44 | E41: ='3 escalar'!D44 | F41: ='3 escalar'!E44 | G41: ='3 escalar'!F44 | H41: ='3 escalar'!G44 | I41: ='3 escalar'!H44 | J41: ='3 escalar'!I44 | ... U41: ='3 escalar'!T44 | V41: =$AC$12+D41*$AC$13+E41*$AC$14+F41*$AC$15+G41*$AC$16+H41*$AC$17+I41*$AC$18+J41*$AC$19+K41*$AC$20+L41*$AC$21+M41*$AC$22+N41*$AC$23+O41*$AC$24+P41*$AC$25+Q41*$AC$26+R41*$AC$27+S41*$AC$28+T41*$AC$29+U41*$AC$30 | W41: =1/(1+EXP(-V41)) | X41: =-IF(C41=1,LN(W41),LN(1-W41)) | Y41: =IF(W41>$AC$32,1,0) | Z41: =IF(Y41=C41,1,0) | AB41: referencia scikit-learn: pérdida promedio training | AC41: 0.50037019 | AG41: churn | AH41: no contactar a quien se iba: se pierde el cliente | AI41: contactar a quien se quedaba: una llamada o un descuento | AJ41: recall, pero el presupuesto de retención es finito, así que precision importa más de lo que parece
A42: ='3 escalar'!A45 | B42: ='3 escalar'!U45 | C42: ='3 escalar'!B45 | D42: ='3 escalar'!C45 | E42: ='3 escalar'!D45 | F42: ='3 escalar'!E45 | G42: ='3 escalar'!F45 | H42: ='3 escalar'!G45 | I42: ='3 escalar'!H45 | J42: ='3 escalar'!I45 | ... U42: ='3 escalar'!T45 | V42: =$AC$12+D42*$AC$13+E42*$AC$14+F42*$AC$15+G42*$AC$16+H42*$AC$17+I42*$AC$18+J42*$AC$19+K42*$AC$20+L42*$AC$21+M42*$AC$22+N42*$AC$23+O42*$AC$24+P42*$AC$25+Q42*$AC$26+R42*$AC$27+S42*$AC$28+T42*$AC$29+U42*$AC$30 | W42: =1/(1+EXP(-V42)) | X42: =-IF(C42=1,LN(W42),LN(1-W42)) | Y42: =IF(W42>$AC$32,1,0) | Z42: =IF(Y42=C42,1,0) | AB42: referencia scikit-learn: pérdida testing | AC42: 0.46905992 | AG42: fraude | AH42: dejar pasar una operación fraudulenta: la pérdida completa | AI42: bloquear una operación legítima: un cliente honesto molesto | AJ42: precision (eficiencia) mantiene tolerable la fricción; recall se sube donde el monto lo justifica
...

Sheet 5 métricas según umbral
A1: Por qué 50%: todas las métricas en testing como función del umbral, y la curva ROC
A2: Por qué 50% y no otro número. El umbral no es parte del modelo; es una decisión. Esta hoja lee los pesos y el umbral de la hoja 4 (conviene tenerlos ya entrenados con Solver, o copiada la columna de referencia) y recalcula la matriz de confusión sobre testing para cada umbral entre 0 y 1 (de 0,05 en 0,05) y muestra cómo se mueven recall, precision, F1 y el acierto. Bajar el umbral atrapa más malos pagadores (sube recall) a costa de marcar más buenos (baja precision); subirlo hace lo contrario. No hay umbral que mejore las dos a la vez: eso es el trade-off, ahora con números.
A3: La curva ROC es esa misma tabla dibujada: en el eje horizontal la tasa de falsos positivos (FP / (FP + TN), qué fracción de los buenos marqué), en el vertical el recall (también llamado tasa de verdaderos positivos). Cada punto es un umbral; recorrer la curva es mover el umbral desde 1 (nadie marcado, esquina inferior izquierda) hasta 0 (todos marcados, esquina superior derecha). Un modelo que adivina al azar sigue la diagonal; uno perfecto sube por el borde izquierdo. El área bajo la curva (AUC) resume qué tan lejos de la diagonal está, y se calcula aquí como suma de trapecios sobre los 21 puntos. Es una aproximación: scikit-learn usa los 300 scores como umbrales y obtiene un área un poco mayor, que se muestra al lado para comparar.
A4: Una lectura complementaria del AUC que conviene conocer: es la probabilidad de que, tomando al azar un mal pagador y un buen pagador, el modelo le haya asignado más riesgo al malo. Es útil para comparar modelos sin fijar umbral, pero esconde el trade-off, y cuando dos curvas ROC se cruzan un solo número no decide nada; ahí hay que mirar la curva en la zona de umbrales que el negocio va a usar.
A5: umbral | B5: TP | C5: FP | D5: TN | E5: FN | F5: acierto | G5: recall (TPR) | H5: precision | I5: F1 | J5: tasa FP (FPR) | K5: trapecio
A6: 1 | B6: =COUNTIFS('4 modelo, umbral y evaluación'!$B$12:$B$1011,"testing",'4 modelo, umbral y evaluación'!$C$12:$C$1011,1,'4 modelo, umbral y evaluación'!$W$12:$W$1011,">"&A6) | C6: =COUNTIFS('4 modelo, umbral y evaluación'!$B$12:$B$1011,"testing",'4 modelo, umbral y evaluación'!$C$12:$C$1011,0,'4 modelo, umbral y evaluación'!$W$12:$W$1011,">"&A6) | D6: =COUNTIFS('4 modelo, umbral y evaluación'!$B$12:$B$1011,"testing",'4 modelo, umbral y evaluación'!$C$12:$C$1011,0,'4 modelo, umbral y evaluación'!$W$12:$W$1011,"<="&A6) | E6: =COUNTIFS('4 modelo, umbral y evaluación'!$B$12:$B$1011,"testing",'4 modelo, umbral y evaluación'!$C$12:$C$1011,1,'4 modelo, umbral y evaluación'!$W$12:$W$1011,"<="&A6) | F6: =(B6+D6)/(B6+C6+D6+E6) | G6: =IF(B6+E6=0,0,B6/(B6+E6)) | H6: =IF(B6+C6=0,0,B6/(B6+C6)) | I6: =IF(G6+H6=0,0,2*G6*H6/(G6+H6)) | J6: =IF(C6+D6=0,0,C6/(C6+D6))
A7: 0.95 | B7: =COUNTIFS('4 modelo, umbral y evaluación'!$B$12:$B$1011,"testing",'4 modelo, umbral y evaluación'!$C$12:$C$1011,1,'4 modelo, umbral y evaluación'!$W$12:$W$1011,">"&A7) | C7: =COUNTIFS('4 modelo, umbral y evaluación'!$B$12:$B$1011,"testing",'4 modelo, umbral y evaluación'!$C$12:$C$1011,0,'4 modelo, umbral y evaluación'!$W$12:$W$1011,">"&A7) | D7: =COUNTIFS('4 modelo, umbral y evaluación'!$B$12:$B$1011,"testing",'4 modelo, umbral y evaluación'!$C$12:$C$1011,0,'4 modelo, umbral y evaluación'!$W$12:$W$1011,"<="&A7) | E7: =COUNTIFS('4 modelo, umbral y evaluación'!$B$12:$B$1011,"testing",'4 modelo, umbral y evaluación'!$C$12:$C$1011,1,'4 modelo, umbral y evaluación'!$W$12:$W$1011,"<="&A7) | F7: =(B7+D7)/(B7+C7+D7+E7) | G7: =IF(B7+E7=0,0,B7/(B7+E7)) | H7: =IF(B7+C7=0,0,B7/(B7+C7)) | I7: =IF(G7+H7=0,0,2*G7*H7/(G7+H7)) | J7: =IF(C7+D7=0,0,C7/(C7+D7)) | K7: =(J7-J6)*(G7+G6)/2
A8: 0.9 | B8: =COUNTIFS('4 modelo, umbral y evaluación'!$B$12:$B$1011,"testing",'4 modelo, umbral y evaluación'!$C$12:$C$1011,1,'4 modelo, umbral y evaluación'!$W$12:$W$1011,">"&A8) | C8: =COUNTIFS('4 modelo, umbral y evaluación'!$B$12:$B$1011,"testing",'4 modelo, umbral y evaluación'!$C$12:$C$1011,0,'4 modelo, umbral y evaluación'!$W$12:$W$1011,">"&A8) | D8: =COUNTIFS('4 modelo, umbral y evaluación'!$B$12:$B$1011,"testing",'4 modelo, umbral y evaluación'!$C$12:$C$1011,0,'4 modelo, umbral y evaluación'!$W$12:$W$1011,"<="&A8) | E8: =COUNTIFS('4 modelo, umbral y evaluación'!$B$12:$B$1011,"testing",'4 modelo, umbral y evaluación'!$C$12:$C$1011,1,'4 modelo, umbral y evaluación'!$W$12:$W$1011,"<="&A8) | F8: =(B8+D8)/(B8+C8+D8+E8) | G8: =IF(B8+E8=0,0,B8/(B8+E8)) | H8: =IF(B8+C8=0,0,B8/(B8+C8)) | I8: =IF(G8+H8=0,0,2*G8*H8/(G8+H8)) | J8: =IF(C8+D8=0,0,C8/(C8+D8)) | K8: =(J8-J7)*(G8+G7)/2
