Workbook

Sheet 0 logic
A1: Logistic regression with regularization: L2 (ridge), L1 (lasso) and elastic net, on German Credit
A2: Prepared by David Díaz, with assistance from Claude (Anthropic).
A4: This workbook is the regularized variant of the base workbook (logistic_01_german_credit_EN.xlsx). It uses exactly the same 1,000 customers, the same 18 columns already transformed and scaled, and the same 700 training / 300 testing split; sheet 1 brings them in as values so the preparation is not repeated. The only thing that changes is the cost function Solver minimizes.
A5: The idea comes from the linear regression classes: when a model is free to move many weights, it tends to fit the noise in training, and one way to rein it in is to charge for the size of the weights. With the logistic it is just as easy: to the sum of the cross-entropy we add a penalty term, and that term is what distinguishes ridge, lasso and elastic net. Ridge (L2) charges λ/2 times the sum of squared weights: it shrinks every weight toward zero, the large ones more, but never leaves any exactly at zero. Lasso (L1) charges λ times the sum of absolute values: it also shrinks, but in addition it leaves weights exactly at zero, that is, it drops variables. Elastic net mixes the two with a parameter α that says what fraction of the penalty is L1. The intercept is never penalized: it says nothing about any variable, it only sets the base level.
A6: Each model sheet (2, 3 and 4) has the customer table with Z, p and loss, the weight block in light blue, the λ cell in light blue, the penalty term computed in plain sight and the cost function J = sum of training losses + penalty, which is Solver's objective cell. The weights start from the unregularized solution (the optimum of the base workbook), so Solver only has to shrink. With λ = 0 each sheet reproduces the base workbook; with large λ the weights go to zero and the model becomes the 'everyone pays' model. Alongside are the confusion matrix and the testing report, and the scikit-learn reference for the same λ.
A7: Sheet 5 compares the three methods for several values of λ, with the weights computed in Python (gray): the path of each weight as λ grows (the classic regularization plot), and the loss and AUC on training and testing. What it shows is honest and worth stating plainly: in this dataset, with 700 customers and 18 variables, the overfitting of the unregularized logistic is mild, so regularization barely improves testing performance; what it does do is stabilize the weights and, with L1, leave a model with fewer variables that performs almost as well. Regularization helps a lot when there are many variables relative to rows, or highly correlated variables, or polynomials; here it mostly helps to understand the mechanics.
A8: A scaling detail that matters when comparing with scikit-learn: its parameter is C = 1 / λ, and it penalizes the sum of the losses (not the average), which is exactly how J is set up in these sheets. That is why the reference weights match Solver's for the same λ. Solver with L1 has a real difficulty: the absolute value is not differentiable at zero, and GRG can leave weights at 0.001 instead of 0; read those weights as zero.
A9: Colors: light blue cells are parameters (weights, λ, α, threshold), yellow cells are intermediate calculations, green cells are results, gray cells are values that come from Python.

Sheet 1 prepared data
A1: The 1,000 customers already transformed and scaled (values; the preparation is in the base workbook, sheets 2 and 3)
A2: Same columns and same split as logistic_01_german_credit_EN.xlsx: y = 1 if defaulter; four numeric columns scaled with the training mean and standard deviation; 14 0/1 columns with their base category; column set with 700 training and 300 testing. They are pasted here as values so this workbook can be opened on its own.
A4: id | B4: y | C4: duration | D4: amount | E4: age | F4: installment_pct_income | G4: chk_negative | H4: chk_0_200 | I4: chk_over_200 | J4: hist_critical | K4: hist_delays | L4: hist_no_credits | M4: sav_100_1000 | N4: sav_over_1000 | O4: sav_unknown | P4: housing_rent | Q4: housing_free | R4: purpose_car | S4: purpose_radio_tv | T4: purpose_furniture | U4: set
A5: 1 | B5: 0 | C5: -1.2412547 | D5: -0.72837022 | E5: 2.7361712 | F5: 0.91854372 | G5: 1 | H5: 0 | I5: 0 | J5: 1 | K5: 0 | L5: 0 | M5: 0 | N5: 0 | O5: 1 | P5: 0 | Q5: 0 | R5: 0 | S5: 1 | T5: 0 | U5: training
A6: 2 | B6: 1 | C6: 2.2976212 | D6: 0.94481687 | E6: -1.1776147 | F6: -0.88504844 | G6: 0 | H6: 1 | I6: 0 | J6: 0 | K6: 0 | L6: 0 | M6: 0 | N6: 0 | O6: 0 | P6: 0 | Q6: 0 | R6: 0 | S6: 1 | T6: 0 | U6: training
A7: 3 | B7: 0 | C7: -0.73570101 | D7: -0.40401965 | E7: 1.1706569 | F7: -0.88504844 | G7: 0 | H7: 0 | I7: 0 | J7: 1 | K7: 0 | L7: 0 | M7: 0 | N7: 0 | O7: 0 | P7: 0 | Q7: 0 | R7: 0 | S7: 0 | T7: 0 | U7: training
A8: 4 | B8: 0 | C8: 1.7920675 | D8: 1.6204598 | E8: 0.82276478 | F8: -0.88504844 | G8: 1 | H8: 0 | I8: 0 | J8: 0 | K8: 0 | L8: 0 | M8: 0 | N8: 0 | O8: 0 | P8: 0 | Q8: 1 | R8: 0 | S8: 0 | T8: 1 | U8: testing
A9: 5 | B9: 1 | C9: 0.2754064 | D9: 0.56658282 | E9: 1.5185489 | F9: 0.016747641 | G9: 1 | H9: 0 | I9: 0 | J9: 0 | K9: 1 | L9: 0 | M9: 0 | N9: 0 | O9: 0 | P9: 0 | Q9: 1 | R9: 1 | S9: 0 | T9: 0 | U9: training
A10: 6 | B10: 0 | C10: 1.2865138 | D10: 2.0308839 | E10: -0.046965431 | F10: -0.88504844 | G10: 0 | H10: 0 | I10: 0 | J10: 0 | K10: 0 | L10: 0 | M10: 0 | N10: 0 | O10: 1 | P10: 0 | Q10: 1 | R10: 0 | S10: 0 | T10: 0 | U10: testing
A11: 7 | B11: 0 | C11: 0.2754064 | D11: -0.14544891 | E11: 1.5185489 | F11: 0.016747641 | G11: 0 | H11: 0 | I11: 0 | J11: 0 | K11: 0 | L11: 0 | M11: 1 | N11: 0 | O11: 0 | P11: 0 | Q11: 0 | R11: 0 | S11: 0 | T11: 1 | U11: training
A12: 8 | B12: 0 | C12: 1.2865138 | D12: 1.2936599 | E12: -0.046965431 | F12: -0.88504844 | G12: 0 | H12: 1 | I12: 0 | J12: 0 | K12: 0 | L12: 0 | M12: 0 | N12: 0 | O12: 0 | P12: 1 | Q12: 0 | R12: 1 | S12: 0 | T12: 0 | U12: training
A13: 9 | B13: 0 | C13: -0.73570101 | D13: -0.067072939 | E13: 2.2143331 | F13: -0.88504844 | G13: 0 | H13: 0 | I13: 0 | J13: 0 | K13: 0 | L13: 0 | M13: 0 | N13: 1 | O13: 0 | P13: 0 | Q13: 0 | R13: 0 | S13: 1 | T13: 0 | U13: training
A14: 10 | B14: 1 | C14: 0.78096011 | D14: 0.69394377 | E14: -0.65577658 | F14: 0.91854372 | G14: 0 | H14: 1 | I14: 0 | J14: 1 | K14: 0 | L14: 0 | M14: 0 | N14: 0 | O14: 0 | P14: 0 | Q14: 0 | R14: 1 | S14: 0 | T14: 0 | U14: training
A15: 11 | B15: 1 | C15: -0.73570101 | D15: -0.68428374 | E15: -0.91669564 | F15: 0.016747641 | G15: 0 | H15: 1 | I15: 0 | J15: 0 | K15: 0 | L15: 0 | M15: 0 | N15: 0 | O15: 0 | P15: 1 | Q15: 0 | R15: 1 | S15: 0 | T15: 0 | U15: training
A16: 12 | B16: 1 | C16: 2.2976212 | D16: 0.3699431 | E16: -1.0036687 | F16: 0.016747641 | G16: 1 | H16: 0 | I16: 0 | J16: 0 | K16: 0 | L16: 0 | M16: 0 | N16: 0 | O16: 0 | P16: 1 | Q16: 0 | R16: 0 | S16: 0 | T16: 0 | U16: training
... A1004: 1000 | B1004: 0 | C1004: 2.0448444 | D1004: 0.46371435 | E1004: -0.7427496 | F1004: 0.016747641 | G1004: 0 | H1004: 1 | I1004: 0 | J1004: 1 | K1004: 0 | L1004: 0 | M1004: 1 | N1004: 0 | O1004: 0 | P1004: 0 | Q1004: 0 | R1004: 1 | S1004: 0 | T1004: 0 | U1004: training

Sheet 2 ridge L2
A1: Ridge (L2): charging for the sum of squared weights
A2: Ridge (L2). The cost function becomes J = Σ losses + λ/2 · Σ theta², with the sum over the 18 weights (the intercept is left out). The new term grows with the square of each weight, so it punishes large weights a lot and small ones little: Solver shrinks them all toward zero, in proportion, but none reaches exactly zero. λ says how much size costs: with λ = 0 we are at the base workbook; with λ = 300 almost every weight is small and the model predicts close to the base rate for everyone.
A3: The weights start from the unregularized solution (light blue column), the gray reference is the scikit-learn solution for λ = 10, and the yellow columns are the theta² values the penalty adds up. Run Solver on J and compare the weights with the reference; then change λ and run it again. Look at the average testing loss: that is what should improve if there were overfitting, and in this dataset it barely moves, because with 700 rows and 18 variables the unregularized model was not overfitting much.
AB10: Weights (theta): start from the unregularized solution of the base workbook | AH10: EVALUATION ON TESTING (with the light blue threshold)
A11: id | B11: set | C11: y | D11: duration | E11: amount | F11: age | G11: installment_pct_income | H11: chk_negative | I11: chk_0_200 | J11: chk_over_200 | K11: hist_critical | L11: hist_delays | M11: hist_no_credits | N11: sav_100_1000 | O11: sav_over_1000 | P11: sav_unknown | Q11: housing_rent | R11: housing_free | S11: purpose_car | T11: purpose_radio_tv | U11: purpose_furniture | V11: Z (line) | W11: p (logistic) | X11: loss | Y11: prediction | Z11: correct | AB11: variable | AC11: theta (light blue) | AD11: scikit-learn reference, λ = 10 | AE11: theta²
A12: ='1 prepared data'!A5 | B12: ='1 prepared data'!U5 | C12: ='1 prepared data'!B5 | D12: ='1 prepared data'!C5 | E12: ='1 prepared data'!D5 | F12: ='1 prepared data'!E5 | G12: ='1 prepared data'!F5 | H12: ='1 prepared data'!G5 | I12: ='1 prepared data'!H5 | J12: ='1 prepared data'!I5 | ... U12: ='1 prepared data'!T5 | V12: =$AC$12+D12*$AC$13+E12*$AC$14+F12*$AC$15+G12*$AC$16+H12*$AC$17+I12*$AC$18+J12*$AC$19+K12*$AC$20+L12*$AC$21+M12*$AC$22+N12*$AC$23+O12*$AC$24+P12*$AC$25+Q12*$AC$26+R12*$AC$27+S12*$AC$28+T12*$AC$29+U12*$AC$30 | W12: =1/(1+EXP(-V12)) | X12: =-IF(C12=1,LN(W12),LN(1-W12)) | Y12: =IF(W12>$AC$33,1,0) | Z12: =IF(Y12=C12,1,0) | AB12: intercept | AC12: -1.341271 | AD12: -1.1287862 | AE12: (not penalized)
A13: ='1 prepared data'!A6 | B13: ='1 prepared data'!U6 | C13: ='1 prepared data'!B6 | D13: ='1 prepared data'!C6 | E13: ='1 prepared data'!D6 | F13: ='1 prepared data'!E6 | G13: ='1 prepared data'!F6 | H13: ='1 prepared data'!G6 | I13: ='1 prepared data'!H6 | J13: ='1 prepared data'!I6 | ... U13: ='1 prepared data'!T6 | V13: =$AC$12+D13*$AC$13+E13*$AC$14+F13*$AC$15+G13*$AC$16+H13*$AC$17+I13*$AC$18+J13*$AC$19+K13*$AC$20+L13*$AC$21+M13*$AC$22+N13*$AC$23+O13*$AC$24+P13*$AC$25+Q13*$AC$26+R13*$AC$27+S13*$AC$28+T13*$AC$29+U13*$AC$30 | W13: =1/(1+EXP(-V13)) | X13: =-IF(C13=1,LN(W13),LN(1-W13)) | Y13: =IF(W13>$AC$33,1,0) | Z13: =IF(Y13=C13,1,0) | AB13: duration | AC13: 0.32470125 | AD13: 0.28934872 | AE13: =AC13^2 | AJ13: predicted 0 | AK13: predicted 1 | AL13: total
A14: ='1 prepared data'!A7 | B14: ='1 prepared data'!U7 | C14: ='1 prepared data'!B7 | D14: ='1 prepared data'!C7 | E14: ='1 prepared data'!D7 | F14: ='1 prepared data'!E7 | G14: ='1 prepared data'!F7 | H14: ='1 prepared data'!G7 | I14: ='1 prepared data'!H7 | J14: ='1 prepared data'!I7 | ... U14: ='1 prepared data'!T7 | V14: =$AC$12+D14*$AC$13+E14*$AC$14+F14*$AC$15+G14*$AC$16+H14*$AC$17+I14*$AC$18+J14*$AC$19+K14*$AC$20+L14*$AC$21+M14*$AC$22+N14*$AC$23+O14*$AC$24+P14*$AC$25+Q14*$AC$26+R14*$AC$27+S14*$AC$28+T14*$AC$29+U14*$AC$30 | W14: =1/(1+EXP(-V14)) | X14: =-IF(C14=1,LN(W14),LN(1-W14)) | Y14: =IF(W14>$AC$33,1,0) | Z14: =IF(Y14=C14,1,0) | AB14: amount | AC14: 0.11635359 | AD14: 0.10179157 | AE14: =AC14^2 | AH14: actual 0 (good payer) | AI14: TN | FP | AJ14: =COUNTIFS($B$12:$B$1011,"testing",$C$12:$C$1011,0,$Y$12:$Y$1011,0) | AK14: =COUNTIFS($B$12:$B$1011,"testing",$C$12:$C$1011,0,$Y$12:$Y$1011,1) | AL14: =AJ14+AK14
A15: ='1 prepared data'!A8 | B15: ='1 prepared data'!U8 | C15: ='1 prepared data'!B8 | D15: ='1 prepared data'!C8 | E15: ='1 prepared data'!D8 | F15: ='1 prepared data'!E8 | G15: ='1 prepared data'!F8 | H15: ='1 prepared data'!G8 | I15: ='1 prepared data'!H8 | J15: ='1 prepared data'!I8 | ... U15: ='1 prepared data'!T8 | V15: =$AC$12+D15*$AC$13+E15*$AC$14+F15*$AC$15+G15*$AC$16+H15*$AC$17+I15*$AC$18+J15*$AC$19+K15*$AC$20+L15*$AC$21+M15*$AC$22+N15*$AC$23+O15*$AC$24+P15*$AC$25+Q15*$AC$26+R15*$AC$27+S15*$AC$28+T15*$AC$29+U15*$AC$30 | W15: =1/(1+EXP(-V15)) | X15: =-IF(C15=1,LN(W15),LN(1-W15)) | Y15: =IF(W15>$AC$33,1,0) | Z15: =IF(Y15=C15,1,0) | AB15: age | AC15: -0.099145225 | AD15: -0.11532177 | AE15: =AC15^2 | AH15: actual 1 (defaulter) | AI15: FN | TP | AJ15: =COUNTIFS($B$12:$B$1011,"testing",$C$12:$C$1011,1,$Y$12:$Y$1011,0) | AK15: =COUNTIFS($B$12:$B$1011,"testing",$C$12:$C$1011,1,$Y$12:$Y$1011,1) | AL15: =AJ15+AK15
A16: ='1 prepared data'!A9 | B16: ='1 prepared data'!U9 | C16: ='1 prepared data'!B9 | D16: ='1 prepared data'!C9 | E16: ='1 prepared data'!D9 | F16: ='1 prepared data'!E9 | G16: ='1 prepared data'!F9 | H16: ='1 prepared data'!G9 | I16: ='1 prepared data'!H9 | J16: ='1 prepared data'!I9 | ... U16: ='1 prepared data'!T9 | V16: =$AC$12+D16*$AC$13+E16*$AC$14+F16*$AC$15+G16*$AC$16+H16*$AC$17+I16*$AC$18+J16*$AC$19+K16*$AC$20+L16*$AC$21+M16*$AC$22+N16*$AC$23+O16*$AC$24+P16*$AC$25+Q16*$AC$26+R16*$AC$27+S16*$AC$28+T16*$AC$29+U16*$AC$30 | W16: =1/(1+EXP(-V16)) | X16: =-IF(C16=1,LN(W16),LN(1-W16)) | Y16: =IF(W16>$AC$33,1,0) | Z16: =IF(Y16=C16,1,0) | AB16: installment_pct_income | AC16: 0.28721577 | AD16: 0.22222887 | AE16: =AC16^2 | AH16: total | AJ16: =AJ14+AJ15 | AK16: =AK14+AK15 | AL16: =AL14+AL15
A17: ='1 prepared data'!A10 | B17: ='1 prepared data'!U10 | C17: ='1 prepared data'!B10 | D17: ='1 prepared data'!C10 | E17: ='1 prepared data'!D10 | F17: ='1 prepared data'!E10 | G17: ='1 prepared data'!F10 | H17: ='1 prepared data'!G10 | I17: ='1 prepared data'!H10 | J17: ='1 prepared data'!I10 | ... U17: ='1 prepared data'!T10 | V17: =$AC$12+D17*$AC$13+E17*$AC$14+F17*$AC$15+G17*$AC$16+H17*$AC$17+I17*$AC$18+J17*$AC$19+K17*$AC$20+L17*$AC$21+M17*$AC$22+N17*$AC$23+O17*$AC$24+P17*$AC$25+Q17*$AC$26+R17*$AC$27+S17*$AC$28+T17*$AC$29+U17*$AC$30 | W17: =1/(1+EXP(-V17)) | X17: =-IF(C17=1,LN(W17),LN(1-W17)) | Y17: =IF(W17>$AC$33,1,0) | Z17: =IF(Y17=C17,1,0) | AB17: chk_negative | AC17: 1.5464027 | AD17: 0.92017635 | AE17: =AC17^2
A18: ='1 prepared data'!A11 | B18: ='1 prepared data'!U11 | C18: ='1 prepared data'!B11 | D18: ='1 prepared data'!C11 | E18: ='1 prepared data'!D11 | F18: ='1 prepared data'!E11 | G18: ='1 prepared data'!F11 | H18: ='1 prepared data'!G11 | I18: ='1 prepared data'!H11 | J18: ='1 prepared data'!I11 | ... U18: ='1 prepared data'!T11 | V18: =$AC$12+D18*$AC$13+E18*$AC$14+F18*$AC$15+G18*$AC$16+H18*$AC$17+I18*$AC$18+J18*$AC$19+K18*$AC$20+L18*$AC$21+M18*$AC$22+N18*$AC$23+O18*$AC$24+P18*$AC$25+Q18*$AC$26+R18*$AC$27+S18*$AC$28+T18*$AC$29+U18*$AC$30 | W18: =1/(1+EXP(-V18)) | X18: =-IF(C18=1,LN(W18),LN(1-W18)) | Y18: =IF(W18>$AC$33,1,0) | Z18: =IF(Y18=C18,1,0) | AB18: chk_0_200 | AC18: 1.2949978 | AD18: 0.69158747 | AE18: =AC18^2 | AI18: precision | AJ18: recall | AK18: f1-score | AL18: support
A19: ='1 prepared data'!A12 | B19: ='1 prepared data'!U12 | C19: ='1 prepared data'!B12 | D19: ='1 prepared data'!C12 | E19: ='1 prepared data'!D12 | F19: ='1 prepared data'!E12 | G19: ='1 prepared data'!F12 | H19: ='1 prepared data'!G12 | I19: ='1 prepared data'!H12 | J19: ='1 prepared data'!I12 | ... U19: ='1 prepared data'!T12 | V19: =$AC$12+D19*$AC$13+E19*$AC$14+F19*$AC$15+G19*$AC$16+H19*$AC$17+I19*$AC$18+J19*$AC$19+K19*$AC$20+L19*$AC$21+M19*$AC$22+N19*$AC$23+O19*$AC$24+P19*$AC$25+Q19*$AC$26+R19*$AC$27+S19*$AC$28+T19*$AC$29+U19*$AC$30 | W19: =1/(1+EXP(-V19)) | X19: =-IF(C19=1,LN(W19),LN(1-W19)) | Y19: =IF(W19>$AC$33,1,0) | Z19: =IF(Y19=C19,1,0) | AB19: chk_over_200 | AC19: 0.66836159 | AD19: 0.082674509 | AE19: =AC19^2 | AH19: class 0 (pays) | AI19: =IF(AJ14+AJ15=0,0,AJ14/(AJ14+AJ15)) | AJ19: =IF(AJ14+AK14=0,0,AJ14/(AJ14+AK14)) | AK19: =IF(AI19+AJ19=0,0,2*AI19*AJ19/(AI19+AJ19)) | AL19: =AL14
A20: ='1 prepared data'!A13 | B20: ='1 prepared data'!U13 | C20: ='1 prepared data'!B13 | D20: ='1 prepared data'!C13 | E20: ='1 prepared data'!D13 | F20: ='1 prepared data'!E13 | G20: ='1 prepared data'!F13 | H20: ='1 prepared data'!G13 | I20: ='1 prepared data'!H13 | J20: ='1 prepared data'!I13 | ... U20: ='1 prepared data'!T13 | V20: =$AC$12+D20*$AC$13+E20*$AC$14+F20*$AC$15+G20*$AC$16+H20*$AC$17+I20*$AC$18+J20*$AC$19+K20*$AC$20+L20*$AC$21+M20*$AC$22+N20*$AC$23+O20*$AC$24+P20*$AC$25+Q20*$AC$26+R20*$AC$27+S20*$AC$28+T20*$AC$29+U20*$AC$30 | W20: =1/(1+EXP(-V20)) | X20: =-IF(C20=1,LN(W20),LN(1-W20)) | Y20: =IF(W20>$AC$33,1,0) | Z20: =IF(Y20=C20,1,0) | AB20: hist_critical | AC20: -0.65734494 | AD20: -0.50285706 | AE20: =AC20^2 | AH20: class 1 (defaults) | AI20: =IF(AK15+AK14=0,0,AK15/(AK15+AK14)) | AJ20: =IF(AK15+AJ15=0,0,AK15/(AK15+AJ15)) | AK20: =IF(AI20+AJ20=0,0,2*AI20*AJ20/(AI20+AJ20)) | AL20: =AL15
A21: ='1 prepared data'!A14 | B21: ='1 prepared data'!U14 | C21: ='1 prepared data'!B14 | D21: ='1 prepared data'!C14 | E21: ='1 prepared data'!D14 | F21: ='1 prepared data'!E14 | G21: ='1 prepared data'!F14 | H21: ='1 prepared data'!G14 | I21: ='1 prepared data'!H14 | J21: ='1 prepared data'!I14 | ... U21: ='1 prepared data'!T14 | V21: =$AC$12+D21*$AC$13+E21*$AC$14+F21*$AC$15+G21*$AC$16+H21*$AC$17+I21*$AC$18+J21*$AC$19+K21*$AC$20+L21*$AC$21+M21*$AC$22+N21*$AC$23+O21*$AC$24+P21*$AC$25+Q21*$AC$26+R21*$AC$27+S21*$AC$28+T21*$AC$29+U21*$AC$30 | W21: =1/(1+EXP(-V21)) | X21: =-IF(C21=1,LN(W21),LN(1-W21)) | Y21: =IF(W21>$AC$33,1,0) | Z21: =IF(Y21=C21,1,0) | AB21: hist_delays | AC21: -0.040195519 | AD21: -0.032989077 | AE21: =AC21^2 | AH21: accuracy | AK21: =(AK15+AJ14)/AL16
A22: ='1 prepared data'!A15 | B22: ='1 prepared data'!U15 | C22: ='1 prepared data'!B15 | D22: ='1 prepared data'!C15 | E22: ='1 prepared data'!D15 | F22: ='1 prepared data'!E15 | G22: ='1 prepared data'!F15 | H22: ='1 prepared data'!G15 | I22: ='1 prepared data'!H15 | J22: ='1 prepared data'!I15 | ... U22: ='1 prepared data'!T15 | V22: =$AC$12+D22*$AC$13+E22*$AC$14+F22*$AC$15+G22*$AC$16+H22*$AC$17+I22*$AC$18+J22*$AC$19+K22*$AC$20+L22*$AC$21+M22*$AC$22+N22*$AC$23+O22*$AC$24+P22*$AC$25+Q22*$AC$26+R22*$AC$27+S22*$AC$28+T22*$AC$29+U22*$AC$30 | W22: =1/(1+EXP(-V22)) | X22: =-IF(C22=1,LN(W22),LN(1-W22)) | Y22: =IF(W22>$AC$33,1,0) | Z22: =IF(Y22=C22,1,0) | AB22: hist_no_credits | AC22: 0.66906563 | AD22: 0.45665963 | AE22: =AC22^2
A23: ='1 prepared data'!A16 | B23: ='1 prepared data'!U16 | C23: ='1 prepared data'!B16 | D23: ='1 prepared data'!C16 | E23: ='1 prepared data'!D16 | F23: ='1 prepared data'!E16 | G23: ='1 prepared data'!F16 | H23: ='1 prepared data'!G16 | I23: ='1 prepared data'!H16 | J23: ='1 prepared data'!I16 | ... U23: ='1 prepared data'!T16 | V23: =$AC$12+D23*$AC$13+E23*$AC$14+F23*$AC$15+G23*$AC$16+H23*$AC$17+I23*$AC$18+J23*$AC$19+K23*$AC$20+L23*$AC$21+M23*$AC$22+N23*$AC$23+O23*$AC$24+P23*$AC$25+Q23*$AC$26+R23*$AC$27+S23*$AC$28+T23*$AC$29+U23*$AC$30 | W23: =1/(1+EXP(-V23)) | X23: =-IF(C23=1,LN(W23),LN(1-W23)) | Y23: =IF(W23>$AC$33,1,0) | Z23: =IF(Y23=C23,1,0) | AB23: sav_100_1000 | AC23: -0.38958343 | AD23: -0.19262314 | AE23: =AC23^2
A24: ='1 prepared data'!A17 | B24: ='1 prepared data'!U17 | C24: ='1 prepared data'!B17 | D24: ='1 prepared data'!C17 | E24: ='1 prepared data'!D17 | F24: ='1 prepared data'!E17 | G24: ='1 prepared data'!F17 | H24: ='1 prepared data'!G17 | I24: ='1 prepared data'!H17 | J24: ='1 prepared data'!I17 | ... U24: ='1 prepared data'!T17 | V24: =$AC$12+D24*$AC$13+E24*$AC$14+F24*$AC$15+G24*$AC$16+H24*$AC$17+I24*$AC$18+J24*$AC$19+K24*$AC$20+L24*$AC$21+M24*$AC$22+N24*$AC$23+O24*$AC$24+P24*$AC$25+Q24*$AC$26+R24*$AC$27+S24*$AC$28+T24*$AC$29+U24*$AC$30 | W24: =1/(1+EXP(-V24)) | X24: =-IF(C24=1,LN(W24),LN(1-W24)) | Y24: =IF(W24>$AC$33,1,0) | Z24: =IF(Y24=C24,1,0) | AB24: sav_over_1000 | AC24: -0.88922386 | AD24: -0.25447519 | AE24: =AC24^2
A25: ='1 prepared data'!A18 | B25: ='1 prepared data'!U18 | C25: ='1 prepared data'!B18 | D25: ='1 prepared data'!C18 | E25: ='1 prepared data'!D18 | F25: ='1 prepared data'!E18 | G25: ='1 prepared data'!F18 | H25: ='1 prepared data'!G18 | I25: ='1 prepared data'!H18 | J25: ='1 prepared data'!I18 | ... U25: ='1 prepared data'!T18 | V25: =$AC$12+D25*$AC$13+E25*$AC$14+F25*$AC$15+G25*$AC$16+H25*$AC$17+I25*$AC$18+J25*$AC$19+K25*$AC$20+L25*$AC$21+M25*$AC$22+N25*$AC$23+O25*$AC$24+P25*$AC$25+Q25*$AC$26+R25*$AC$27+S25*$AC$28+T25*$AC$29+U25*$AC$30 | W25: =1/(1+EXP(-V25)) | X25: =-IF(C25=1,LN(W25),LN(1-W25)) | Y25: =IF(W25>$AC$33,1,0) | Z25: =IF(Y25=C25,1,0) | AB25: sav_unknown | AC25: -1.0760929 | AD25: -0.58281045 | AE25: =AC25^2
A26: ='1 prepared data'!A19 | B26: ='1 prepared data'!U19 | C26: ='1 prepared data'!B19 | D26: ='1 prepared data'!C19 | E26: ='1 prepared data'!D19 | F26: ='1 prepared data'!E19 | G26: ='1 prepared data'!F19 | H26: ='1 prepared data'!G19 | I26: ='1 prepared data'!H19 | J26: ='1 prepared data'!I19 | ... U26: ='1 prepared data'!T19 | V26: =$AC$12+D26*$AC$13+E26*$AC$14+F26*$AC$15+G26*$AC$16+H26*$AC$17+I26*$AC$18+J26*$AC$19+K26*$AC$20+L26*$AC$21+M26*$AC$22+N26*$AC$23+O26*$AC$24+P26*$AC$25+Q26*$AC$26+R26*$AC$27+S26*$AC$28+T26*$AC$29+U26*$AC$30 | W26: =1/(1+EXP(-V26)) | X26: =-IF(C26=1,LN(W26),LN(1-W26)) | Y26: =IF(W26>$AC$33,1,0) | Z26: =IF(Y26=C26,1,0) | AB26: housing_rent | AC26: 0.65383718 | AD26: 0.38387334 | AE26: =AC26^2
A27: ='1 prepared data'!A20 | B27: ='1 prepared data'!U20 | C27: ='1 prepared data'!B20 | D27: ='1 prepared data'!C20 | E27: ='1 prepared data'!D20 | F27: ='1 prepared data'!E20 | G27: ='1 prepared data'!F20 | H27: ='1 prepared data'!G20 | I27: ='1 prepared data'!H20 | J27: ='1 prepared data'!I20 | ... U27: ='1 prepared data'!T20 | V27: =$AC$12+D27*$AC$13+E27*$AC$14+F27*$AC$15+G27*$AC$16+H27*$AC$17+I27*$AC$18+J27*$AC$19+K27*$AC$20+L27*$AC$21+M27*$AC$22+N27*$AC$23+O27*$AC$24+P27*$AC$25+Q27*$AC$26+R27*$AC$27+S27*$AC$28+T27*$AC$29+U27*$AC$30 | W27: =1/(1+EXP(-V27)) | X27: =-IF(C27=1,LN(W27),LN(1-W27)) | Y27: =IF(W27>$AC$33,1,0) | Z27: =IF(Y27=C27,1,0) | AB27: housing_free | AC27: 0.19536536 | AD27: 0.15826888 | AE27: =AC27^2
A28: ='1 prepared data'!A21 | B28: ='1 prepared data'!U21 | C28: ='1 prepared data'!B21 | D28: ='1 prepared data'!C21 | E28: ='1 prepared data'!D21 | F28: ='1 prepared data'!E21 | G28: ='1 prepared data'!F21 | H28: ='1 prepared data'!G21 | I28: ='1 prepared data'!H21 | J28: ='1 prepared data'!I21 | ... U28: ='1 prepared data'!T21 | V28: =$AC$12+D28*$AC$13+E28*$AC$14+F28*$AC$15+G28*$AC$16+H28*$AC$17+I28*$AC$18+J28*$AC$19+K28*$AC$20+L28*$AC$21+M28*$AC$22+N28*$AC$23+O28*$AC$24+P28*$AC$25+Q28*$AC$26+R28*$AC$27+S28*$AC$28+T28*$AC$29+U28*$AC$30 | W28: =1/(1+EXP(-V28)) | X28: =-IF(C28=1,LN(W28),LN(1-W28)) | Y28: =IF(W28>$AC$33,1,0) | Z28: =IF(Y28=C28,1,0) | AB28: purpose_car | AC28: -0.080165476 | AD28: 0.034595626 | AE28: =AC28^2
A29: ='1 prepared data'!A22 | B29: ='1 prepared data'!U22 | C29: ='1 prepared data'!B22 | D29: ='1 prepared data'!C22 | E29: ='1 prepared data'!D22 | F29: ='1 prepared data'!E22 | G29: ='1 prepared data'!F22 | H29: ='1 prepared data'!G22 | I29: ='1 prepared data'!H22 | J29: ='1 prepared data'!I22 | ... U29: ='1 prepared data'!T22 | V29: =$AC$12+D29*$AC$13+E29*$AC$14+F29*$AC$15+G29*$AC$16+H29*$AC$17+I29*$AC$18+J29*$AC$19+K29*$AC$20+L29*$AC$21+M29*$AC$22+N29*$AC$23+O29*$AC$24+P29*$AC$25+Q29*$AC$26+R29*$AC$27+S29*$AC$28+T29*$AC$29+U29*$AC$30 | W29: =1/(1+EXP(-V29)) | X29: =-IF(C29=1,LN(W29),LN(1-W29)) | Y29: =IF(W29>$AC$33,1,0) | Z29: =IF(Y29=C29,1,0) | AB29: purpose_radio_tv | AC29: -0.52021065 | AD29: -0.3058125 | AE29: =AC29^2
A30: ='1 prepared data'!A23 | B30: ='1 prepared data'!U23 | C30: ='1 prepared data'!B23 | D30: ='1 prepared data'!C23 | E30: ='1 prepared data'!D23 | F30: ='1 prepared data'!E23 | G30: ='1 prepared data'!F23 | H30: ='1 prepared data'!G23 | I30: ='1 prepared data'!H23 | J30: ='1 prepared data'!I23 | ... U30: ='1 prepared data'!T23 | V30: =$AC$12+D30*$AC$13+E30*$AC$14+F30*$AC$15+G30*$AC$16+H30*$AC$17+I30*$AC$18+J30*$AC$19+K30*$AC$20+L30*$AC$21+M30*$AC$22+N30*$AC$23+O30*$AC$24+P30*$AC$25+Q30*$AC$26+R30*$AC$27+S30*$AC$28+T30*$AC$29+U30*$AC$30 | W30: =1/(1+EXP(-V30)) | X30: =-IF(C30=1,LN(W30),LN(1-W30)) | Y30: =IF(W30>$AC$33,1,0) | Z30: =IF(Y30=C30,1,0) | AB30: purpose_furniture | AC30: -0.28180274 | AD30: -0.025436476 | AE30: =AC30^2
A31: ='1 prepared data'!A24 | B31: ='1 prepared data'!U24 | C31: ='1 prepared data'!B24 | D31: ='1 prepared data'!C24 | E31: ='1 prepared data'!D24 | F31: ='1 prepared data'!E24 | G31: ='1 prepared data'!F24 | H31: ='1 prepared data'!G24 | I31: ='1 prepared data'!H24 | J31: ='1 prepared data'!I24 | ... U31: ='1 prepared data'!T24 | V31: =$AC$12+D31*$AC$13+E31*$AC$14+F31*$AC$15+G31*$AC$16+H31*$AC$17+I31*$AC$18+J31*$AC$19+K31*$AC$20+L31*$AC$21+M31*$AC$22+N31*$AC$23+O31*$AC$24+P31*$AC$25+Q31*$AC$26+R31*$AC$27+S31*$AC$28+T31*$AC$29+U31*$AC$30 | W31: =1/(1+EXP(-V31)) | X31: =-IF(C31=1,LN(W31),LN(1-W31)) | Y31: =IF(W31>$AC$33,1,0) | Z31: =IF(Y31=C31,1,0)
A32: ='1 prepared data'!A25 | B32: ='1 prepared data'!U25 | C32: ='1 prepared data'!B25 | D32: ='1 prepared data'!C25 | E32: ='1 prepared data'!D25 | F32: ='1 prepared data'!E25 | G32: ='1 prepared data'!F25 | H32: ='1 prepared data'!G25 | I32: ='1 prepared data'!H25 | J32: ='1 prepared data'!I25 | ... U32: ='1 prepared data'!T25 | V32: =$AC$12+D32*$AC$13+E32*$AC$14+F32*$AC$15+G32*$AC$16+H32*$AC$17+I32*$AC$18+J32*$AC$19+K32*$AC$20+L32*$AC$21+M32*$AC$22+N32*$AC$23+O32*$AC$24+P32*$AC$25+Q32*$AC$26+R32*$AC$27+S32*$AC$28+T32*$AC$29+U32*$AC$30 | W32: =1/(1+EXP(-V32)) | X32: =-IF(C32=1,LN(W32),LN(1-W32)) | Y32: =IF(W32>$AC$33,1,0) | Z32: =IF(Y32=C32,1,0) | AB32: λ (lambda): how much the size of the weights costs | AC32: 10
A33: ='1 prepared data'!A26 | B33: ='1 prepared data'!U26 | C33: ='1 prepared data'!B26 | D33: ='1 prepared data'!C26 | E33: ='1 prepared data'!D26 | F33: ='1 prepared data'!E26 | G33: ='1 prepared data'!F26 | H33: ='1 prepared data'!G26 | I33: ='1 prepared data'!H26 | J33: ='1 prepared data'!I26 | ... U33: ='1 prepared data'!T26 | V33: =$AC$12+D33*$AC$13+E33*$AC$14+F33*$AC$15+G33*$AC$16+H33*$AC$17+I33*$AC$18+J33*$AC$19+K33*$AC$20+L33*$AC$21+M33*$AC$22+N33*$AC$23+O33*$AC$24+P33*$AC$25+Q33*$AC$26+R33*$AC$27+S33*$AC$28+T33*$AC$29+U33*$AC$30 | W33: =1/(1+EXP(-V33)) | X33: =-IF(C33=1,LN(W33),LN(1-W33)) | Y33: =IF(W33>$AC$33,1,0) | Z33: =IF(Y33=C33,1,0) | AB33: threshold | AC33: 0.5
A34: ='1 prepared data'!A27 | B34: ='1 prepared data'!U27 | C34: ='1 prepared data'!B27 | D34: ='1 prepared data'!C27 | E34: ='1 prepared data'!D27 | F34: ='1 prepared data'!E27 | G34: ='1 prepared data'!F27 | H34: ='1 prepared data'!G27 | I34: ='1 prepared data'!H27 | J34: ='1 prepared data'!I27 | ... U34: ='1 prepared data'!T27 | V34: =$AC$12+D34*$AC$13+E34*$AC$14+F34*$AC$15+G34*$AC$16+H34*$AC$17+I34*$AC$18+J34*$AC$19+K34*$AC$20+L34*$AC$21+M34*$AC$22+N34*$AC$23+O34*$AC$24+P34*$AC$25+Q34*$AC$26+R34*$AC$27+S34*$AC$28+T34*$AC$29+U34*$AC$30 | W34: =1/(1+EXP(-V34)) | X34: =-IF(C34=1,LN(W34),LN(1-W34)) | Y34: =IF(W34>$AC$33,1,0) | Z34: =IF(Y34=C34,1,0)
A35: ='1 prepared data'!A28 | B35: ='1 prepared data'!U28 | C35: ='1 prepared data'!B28 | D35: ='1 prepared data'!C28 | E35: ='1 prepared data'!D28 | F35: ='1 prepared data'!E28 | G35: ='1 prepared data'!F28 | H35: ='1 prepared data'!G28 | I35: ='1 prepared data'!H28 | J35: ='1 prepared data'!I28 | ... U35: ='1 prepared data'!T28 | V35: =$AC$12+D35*$AC$13+E35*$AC$14+F35*$AC$15+G35*$AC$16+H35*$AC$17+I35*$AC$18+J35*$AC$19+K35*$AC$20+L35*$AC$21+M35*$AC$22+N35*$AC$23+O35*$AC$24+P35*$AC$25+Q35*$AC$26+R35*$AC$27+S35*$AC$28+T35*$AC$29+U35*$AC$30 | W35: =1/(1+EXP(-V35)) | X35: =-IF(C35=1,LN(W35),LN(1-W35)) | Y35: =IF(W35>$AC$33,1,0) | Z35: =IF(Y35=C35,1,0) | AB35: RESULTS
A36: ='1 prepared data'!A29 | B36: ='1 prepared data'!U29 | C36: ='1 prepared data'!B29 | D36: ='1 prepared data'!C29 | E36: ='1 prepared data'!D29 | F36: ='1 prepared data'!E29 | G36: ='1 prepared data'!F29 | H36: ='1 prepared data'!G29 | I36: ='1 prepared data'!H29 | J36: ='1 prepared data'!I29 | ... U36: ='1 prepared data'!T29 | V36: =$AC$12+D36*$AC$13+E36*$AC$14+F36*$AC$15+G36*$AC$16+H36*$AC$17+I36*$AC$18+J36*$AC$19+K36*$AC$20+L36*$AC$21+M36*$AC$22+N36*$AC$23+O36*$AC$24+P36*$AC$25+Q36*$AC$26+R36*$AC$27+S36*$AC$28+T36*$AC$29+U36*$AC$30 | W36: =1/(1+EXP(-V36)) | X36: =-IF(C36=1,LN(W36),LN(1-W36)) | Y36: =IF(W36>$AC$33,1,0) | Z36: =IF(Y36=C36,1,0) | AB36: sum of training losses | AC36: =SUMPRODUCT(($B$12:$B$1011="training")*$X$12:$X$1011)
A37: ='1 prepared data'!A30 | B37: ='1 prepared data'!U30 | C37: ='1 prepared data'!B30 | D37: ='1 prepared data'!C30 | E37: ='1 prepared data'!D30 | F37: ='1 prepared data'!E30 | G37: ='1 prepared data'!F30 | H37: ='1 prepared data'!G30 | I37: ='1 prepared data'!H30 | J37: ='1 prepared data'!I30 | ... U37: ='1 prepared data'!T30 | V37: =$AC$12+D37*$AC$13+E37*$AC$14+F37*$AC$15+G37*$AC$16+H37*$AC$17+I37*$AC$18+J37*$AC$19+K37*$AC$20+L37*$AC$21+M37*$AC$22+N37*$AC$23+O37*$AC$24+P37*$AC$25+Q37*$AC$26+R37*$AC$27+S37*$AC$28+T37*$AC$29+U37*$AC$30 | W37: =1/(1+EXP(-V37)) | X37: =-IF(C37=1,LN(W37),LN(1-W37)) | Y37: =IF(W37>$AC$33,1,0) | Z37: =IF(Y37=C37,1,0) | AB37: L2 penalty = λ/2 · Σ theta² | AC37: =$AC$32/2*SUM($AE$13:$AE$30)
A38: ='1 prepared data'!A31 | B38: ='1 prepared data'!U31 | C38: ='1 prepared data'!B31 | D38: ='1 prepared data'!C31 | E38: ='1 prepared data'!D31 | F38: ='1 prepared data'!E31 | G38: ='1 prepared data'!F31 | H38: ='1 prepared data'!G31 | I38: ='1 prepared data'!H31 | J38: ='1 prepared data'!I31 | ... U38: ='1 prepared data'!T31 | V38: =$AC$12+D38*$AC$13+E38*$AC$14+F38*$AC$15+G38*$AC$16+H38*$AC$17+I38*$AC$18+J38*$AC$19+K38*$AC$20+L38*$AC$21+M38*$AC$22+N38*$AC$23+O38*$AC$24+P38*$AC$25+Q38*$AC$26+R38*$AC$27+S38*$AC$28+T38*$AC$29+U38*$AC$30 | W38: =1/(1+EXP(-V38)) | X38: =-IF(C38=1,LN(W38),LN(1-W38)) | Y38: =IF(W38>$AC$33,1,0) | Z38: =IF(Y38=C38,1,0) | AB38: J = sum of losses + penalty (SOLVER OBJECTIVE) | AC38: =AC36+AC37
A39: ='1 prepared data'!A32 | B39: ='1 prepared data'!U32 | C39: ='1 prepared data'!B32 | D39: ='1 prepared data'!C32 | E39: ='1 prepared data'!D32 | F39: ='1 prepared data'!E32 | G39: ='1 prepared data'!F32 | H39: ='1 prepared data'!G32 | I39: ='1 prepared data'!H32 | J39: ='1 prepared data'!I32 | ... U39: ='1 prepared data'!T32 | V39: =$AC$12+D39*$AC$13+E39*$AC$14+F39*$AC$15+G39*$AC$16+H39*$AC$17+I39*$AC$18+J39*$AC$19+K39*$AC$20+L39*$AC$21+M39*$AC$22+N39*$AC$23+O39*$AC$24+P39*$AC$25+Q39*$AC$26+R39*$AC$27+S39*$AC$28+T39*$AC$29+U39*$AC$30 | W39: =1/(1+EXP(-V39)) | X39: =-IF(C39=1,LN(W39),LN(1-W39)) | Y39: =IF(W39>$AC$33,1,0) | Z39: =IF(Y39=C39,1,0) | AB39: average training loss | AC39: =AC36/COUNTIF($B$12:$B$1011,"training")
A40: ='1 prepared data'!A33 | B40: ='1 prepared data'!U33 | C40: ='1 prepared data'!B33 | D40: ='1 prepared data'!C33 | E40: ='1 prepared data'!D33 | F40: ='1 prepared data'!E33 | G40: ='1 prepared data'!F33 | H40: ='1 prepared data'!G33 | I40: ='1 prepared data'!H33 | J40: ='1 prepared data'!I33 | ... U40: ='1 prepared data'!T33 | V40: =$AC$12+D40*$AC$13+E40*$AC$14+F40*$AC$15+G40*$AC$16+H40*$AC$17+I40*$AC$18+J40*$AC$19+K40*$AC$20+L40*$AC$21+M40*$AC$22+N40*$AC$23+O40*$AC$24+P40*$AC$25+Q40*$AC$26+R40*$AC$27+S40*$AC$28+T40*$AC$29+U40*$AC$30 | W40: =1/(1+EXP(-V40)) | X40: =-IF(C40=1,LN(W40),LN(1-W40)) | Y40: =IF(W40>$AC$33,1,0) | Z40: =IF(Y40=C40,1,0) | AB40: average testing loss | AC40: =SUMPRODUCT(($B$12:$B$1011="testing")*$X$12:$X$1011)/COUNTIF($B$12:$B$1011,"testing")
A41: ='1 prepared data'!A34 | B41: ='1 prepared data'!U34 | C41: ='1 prepared data'!B34 | D41: ='1 prepared data'!C34 | E41: ='1 prepared data'!D34 | F41: ='1 prepared data'!E34 | G41: ='1 prepared data'!F34 | H41: ='1 prepared data'!G34 | I41: ='1 prepared data'!H34 | J41: ='1 prepared data'!I34 | ... U41: ='1 prepared data'!T34 | V41: =$AC$12+D41*$AC$13+E41*$AC$14+F41*$AC$15+G41*$AC$16+H41*$AC$17+I41*$AC$18+J41*$AC$19+K41*$AC$20+L41*$AC$21+M41*$AC$22+N41*$AC$23+O41*$AC$24+P41*$AC$25+Q41*$AC$26+R41*$AC$27+S41*$AC$28+T41*$AC$29+U41*$AC$30 | W41: =1/(1+EXP(-V41)) | X41: =-IF(C41=1,LN(W41),LN(1-W41)) | Y41: =IF(W41>$AC$33,1,0) | Z41: =IF(Y41=C41,1,0) | AB41: testing accuracy | AC41: =SUMPRODUCT(($B$12:$B$1011="testing")*$Z$12:$Z$1011)/COUNTIF($B$12:$B$1011,"testing")
A42: ='1 prepared data'!A35 | B42: ='1 prepared data'!U35 | C42: ='1 prepared data'!B35 | D42: ='1 prepared data'!C35 | E42: ='1 prepared data'!D35 | F42: ='1 prepared data'!E35 | G42: ='1 prepared data'!F35 | H42: ='1 prepared data'!G35 | I42: ='1 prepared data'!H35 | J42: ='1 prepared data'!I35 | ... U42: ='1 prepared data'!T35 | V42: =$AC$12+D42*$AC$13+E42*$AC$14+F42*$AC$15+G42*$AC$16+H42*$AC$17+I42*$AC$18+J42*$AC$19+K42*$AC$20+L42*$AC$21+M42*$AC$22+N42*$AC$23+O42*$AC$24+P42*$AC$25+Q42*$AC$26+R42*$AC$27+S42*$AC$28+T42*$AC$29+U42*$AC$30 | W42: =1/(1+EXP(-V42)) | X42: =-IF(C42=1,LN(W42),LN(1-W42)) | Y42: =IF(W42>$AC$33,1,0) | Z42: =IF(Y42=C42,1,0) | AB42: weights (excluding intercept) with |theta| < 0.01 | AC42: =COUNTIF(AC13:AC30,"<0.01")-COUNTIF(AC13:AC30,"<-0.01")
A43: ='1 prepared data'!A36 | B43: ='1 prepared data'!U36 | C43: ='1 prepared data'!B36 | D43: ='1 prepared data'!C36 | E43: ='1 prepared data'!D36 | F43: ='1 prepared data'!E36 | G43: ='1 prepared data'!F36 | H43: ='1 prepared data'!G36 | I43: ='1 prepared data'!H36 | J43: ='1 prepared data'!I36 | ... U43: ='1 prepared data'!T36 | V43: =$AC$12+D43*$AC$13+E43*$AC$14+F43*$AC$15+G43*$AC$16+H43*$AC$17+I43*$AC$18+J43*$AC$19+K43*$AC$20+L43*$AC$21+M43*$AC$22+N43*$AC$23+O43*$AC$24+P43*$AC$25+Q43*$AC$26+R43*$AC$27+S43*$AC$28+T43*$AC$29+U43*$AC$30 | W43: =1/(1+EXP(-V43)) | X43: =-IF(C43=1,LN(W43),LN(1-W43)) | Y43: =IF(W43>$AC$33,1,0) | Z43: =IF(Y43=C43,1,0) | AB43: scikit-learn reference (λ = 10): J | AC43: 372.52712
A44: ='1 prepared data'!A37 | B44: ='1 prepared data'!U37 | C44: ='1 prepared data'!B37 | D44: ='1 prepared data'!C37 | E44: ='1 prepared data'!D37 | F44: ='1 prepared data'!E37 | G44: ='1 prepared data'!F37 | H44: ='1 prepared data'!G37 | I44: ='1 prepared data'!H37 | J44: ='1 prepared data'!I37 | ... U44: ='1 prepared data'!T37 | V44: =$AC$12+D44*$AC$13+E44*$AC$14+F44*$AC$15+G44*$AC$16+H44*$AC$17+I44*$AC$18+J44*$AC$19+K44*$AC$20+L44*$AC$21+M44*$AC$22+N44*$AC$23+O44*$AC$24+P44*$AC$25+Q44*$AC$26+R44*$AC$27+S44*$AC$28+T44*$AC$29+U44*$AC$30 | W44: =1/(1+EXP(-V44)) | X44: =-IF(C44=1,LN(W44),LN(1-W44)) | Y44: =IF(W44>$AC$33,1,0) | Z44: =IF(Y44=C44,1,0) | AB44: scikit-learn reference (λ = 10): average testing loss | AC44: 0.48479331
A45: ='1 prepared data'!A38 | B45: ='1 prepared data'!U38 | C45: ='1 prepared data'!B38 | D45: ='1 prepared data'!C38 | E45: ='1 prepared data'!D38 | F45: ='1 prepared data'!E38 | G45: ='1 prepared data'!F38 | H45: ='1 prepared data'!G38 | I45: ='1 prepared data'!H38 | J45: ='1 prepared data'!I38 | ... U45: ='1 prepared data'!T38 | V45: =$AC$12+D45*$AC$13+E45*$AC$14+F45*$AC$15+G45*$AC$16+H45*$AC$17+I45*$AC$18+J45*$AC$19+K45*$AC$20+L45*$AC$21+M45*$AC$22+N45*$AC$23+O45*$AC$24+P45*$AC$25+Q45*$AC$26+R45*$AC$27+S45*$AC$28+T45*$AC$29+U45*$AC$30 | W45: =1/(1+EXP(-V45)) | X45: =-IF(C45=1,LN(W45),LN(1-W45)) | Y45: =IF(W45>$AC$33,1,0) | Z45: =IF(Y45=C45,1,0) | AB45: scikit-learn reference (λ = 10): weights at zero | AC45: 0
A46: ='1 prepared data'!A39 | B46: ='1 prepared data'!U39 | C46: ='1 prepared data'!B39 | D46: ='1 prepared data'!C39 | E46: ='1 prepared data'!D39 | F46: ='1 prepared data'!E39 | G46: ='1 prepared data'!F39 | H46: ='1 prepared data'!G39 | I46: ='1 prepared data'!H39 | J46: ='1 prepared data'!I39 | ... U46: ='1 prepared data'!T39 | V46: =$AC$12+D46*$AC$13+E46*$AC$14+F46*$AC$15+G46*$AC$16+H46*$AC$17+I46*$AC$18+J46*$AC$19+K46*$AC$20+L46*$AC$21+M46*$AC$22+N46*$AC$23+O46*$AC$24+P46*$AC$25+Q46*$AC$26+R46*$AC$27+S46*$AC$28+T46*$AC$29+U46*$AC$30 | W46: =1/(1+EXP(-V46)) | X46: =-IF(C46=1,LN(W46),LN(1-W46)) | Y46: =IF(W46>$AC$33,1,0) | Z46: =IF(Y46=C46,1,0) | AB46: unregularized reference (base workbook): average testing loss | AC46: 0.46905992
...

Sheet 3 lasso L1
A1: Lasso (L1): charging for the sum of absolute values, and leaving weights at zero
A2: Lasso (L1). Now J = Σ losses + λ · Σ |theta|. The difference from ridge looks like a detail and is not: the absolute value has the same slope λ for a large weight as for a small one, so the small weights, which contribute little to the loss, end up exactly at zero. Lasso does variable selection: with λ = 10, seven of the 18 weights are zero in scikit-learn, and the model is left with eleven variables that perform almost as well. It is the simplest way to answer 'which variables really matter' without leaving the logistic.
A3: Solver and the absolute value do not get along, because |theta| has no derivative at zero: GRG gets close and leaves weights at 0.002 or −0.004 instead of exactly 0. The cell 'weights with |theta| < 0.01' counts them as zero; compare it with the reference. If Solver gets stuck, run it twice, or start from the gray reference and check that J does not go down.
AB10: Weights (theta): start from the unregularized solution of the base workbook | AH10: EVALUATION ON TESTING (with the light blue threshold)
A11: id | B11: set | C11: y | D11: duration | E11: amount | F11: age | G11: installment_pct_income | H11: chk_negative | I11: chk_0_200 | J11: chk_over_200 | K11: hist_critical | L11: hist_delays | M11: hist_no_credits | N11: sav_100_1000 | O11: sav_over_1000 | P11: sav_unknown | Q11: housing_rent | R11: housing_free | S11: purpose_car | T11: purpose_radio_tv | U11: purpose_furniture | V11: Z (line) | W11: p (logistic) | X11: loss | Y11: prediction | Z11: correct | AB11: variable | AC11: theta (light blue) | AD11: scikit-learn reference, λ = 10 | AE11: |theta|
A12: ='1 prepared data'!A5 | B12: ='1 prepared data'!U5 | C12: ='1 prepared data'!B5 | D12: ='1 prepared data'!C5 | E12: ='1 prepared data'!D5 | F12: ='1 prepared data'!E5 | G12: ='1 prepared data'!F5 | H12: ='1 prepared data'!G5 | I12: ='1 prepared data'!H5 | J12: ='1 prepared data'!I5 | ... U12: ='1 prepared data'!T5 | V12: =$AC$12+D12*$AC$13+E12*$AC$14+F12*$AC$15+G12*$AC$16+H12*$AC$17+I12*$AC$18+J12*$AC$19+K12*$AC$20+L12*$AC$21+M12*$AC$22+N12*$AC$23+O12*$AC$24+P12*$AC$25+Q12*$AC$26+R12*$AC$27+S12*$AC$28+T12*$AC$29+U12*$AC$30 | W12: =1/(1+EXP(-V12)) | X12: =-IF(C12=1,LN(W12),LN(1-W12)) | Y12: =IF(W12>$AC$33,1,0) | Z12: =IF(Y12=C12,1,0) | AB12: intercept | AC12: -1.341271 | AD12: -1.1904713 | AE12: (not penalized)
A13: ='1 prepared data'!A6 | B13: ='1 prepared data'!U6 | C13: ='1 prepared data'!B6 | D13: ='1 prepared data'!C6 | E13: ='1 prepared data'!D6 | F13: ='1 prepared data'!E6 | G13: ='1 prepared data'!F6 | H13: ='1 prepared data'!G6 | I13: ='1 prepared data'!H6 | J13: ='1 prepared data'!I6 | ... U13: ='1 prepared data'!T6 | V13: =$AC$12+D13*$AC$13+E13*$AC$14+F13*$AC$15+G13*$AC$16+H13*$AC$17+I13*$AC$18+J13*$AC$19+K13*$AC$20+L13*$AC$21+M13*$AC$22+N13*$AC$23+O13*$AC$24+P13*$AC$25+Q13*$AC$26+R13*$AC$27+S13*$AC$28+T13*$AC$29+U13*$AC$30 | W13: =1/(1+EXP(-V13)) | X13: =-IF(C13=1,LN(W13),LN(1-W13)) | Y13: =IF(W13>$AC$33,1,0) | Z13: =IF(Y13=C13,1,0) | AB13: duration | AC13: 0.32470125 | AD13: 0.29144233 | AE13: =ABS(AC13) | AJ13: predicted 0 | AK13: predicted 1 | AL13: total
A14: ='1 prepared data'!A7 | B14: ='1 prepared data'!U7 | C14: ='1 prepared data'!B7 | D14: ='1 prepared data'!C7 | E14: ='1 prepared data'!D7 | F14: ='1 prepared data'!E7 | G14: ='1 prepared data'!F7 | H14: ='1 prepared data'!G7 | I14: ='1 prepared data'!H7 | J14: ='1 prepared data'!I7 | ... U14: ='1 prepared data'!T7 | V14: =$AC$12+D14*$AC$13+E14*$AC$14+F14*$AC$15+G14*$AC$16+H14*$AC$17+I14*$AC$18+J14*$AC$19+K14*$AC$20+L14*$AC$21+M14*$AC$22+N14*$AC$23+O14*$AC$24+P14*$AC$25+Q14*$AC$26+R14*$AC$27+S14*$AC$28+T14*$AC$29+U14*$AC$30 | W14: =1/(1+EXP(-V14)) | X14: =-IF(C14=1,LN(W14),LN(1-W14)) | Y14: =IF(W14>$AC$33,1,0) | Z14: =IF(Y14=C14,1,0) | AB14: amount | AC14: 0.11635359 | AD14: 0.014975721 | AE14: =ABS(AC14) | AH14: actual 0 (good payer) | AI14: TN | FP | AJ14: =COUNTIFS($B$12:$B$1011,"testing",$C$12:$C$1011,0,$Y$12:$Y$1011,0) | AK14: =COUNTIFS($B$12:$B$1011,"testing",$C$12:$C$1011,0,$Y$12:$Y$1011,1) | AL14: =AJ14+AK14
A15: ='1 prepared data'!A8 | B15: ='1 prepared data'!U8 | C15: ='1 prepared data'!B8 | D15: ='1 prepared data'!C8 | E15: ='1 prepared data'!D8 | F15: ='1 prepared data'!E8 | G15: ='1 prepared data'!F8 | H15: ='1 prepared data'!G8 | I15: ='1 prepared data'!H8 | J15: ='1 prepared data'!I8 | ... U15: ='1 prepared data'!T8 | V15: =$AC$12+D15*$AC$13+E15*$AC$14+F15*$AC$15+G15*$AC$16+H15*$AC$17+I15*$AC$18+J15*$AC$19+K15*$AC$20+L15*$AC$21+M15*$AC$22+N15*$AC$23+O15*$AC$24+P15*$AC$25+Q15*$AC$26+R15*$AC$27+S15*$AC$28+T15*$AC$29+U15*$AC$30 | W15: =1/(1+EXP(-V15)) | X15: =-IF(C15=1,LN(W15),LN(1-W15)) | Y15: =IF(W15>$AC$33,1,0) | Z15: =IF(Y15=C15,1,0) | AB15: age | AC15: -0.099145225 | AD15: -0.044617039 | AE15: =ABS(AC15) | AH15: actual 1 (defaulter) | AI15: FN | TP | AJ15: =COUNTIFS($B$12:$B$1011,"testing",$C$12:$C$1011,1,$Y$12:$Y$1011,0) | AK15: =COUNTIFS($B$12:$B$1011,"testing",$C$12:$C$1011,1,$Y$12:$Y$1011,1) | AL15: =AJ15+AK15
A16: ='1 prepared data'!A9 | B16: ='1 prepared data'!U9 | C16: ='1 prepared data'!B9 | D16: ='1 prepared data'!C9 | E16: ='1 prepared data'!D9 | F16: ='1 prepared data'!E9 | G16: ='1 prepared data'!F9 | H16: ='1 prepared data'!G9 | I16: ='1 prepared data'!H9 | J16: ='1 prepared data'!I9 | ... U16: ='1 prepared data'!T9 | V16: =$AC$12+D16*$AC$13+E16*$AC$14+F16*$AC$15+G16*$AC$16+H16*$AC$17+I16*$AC$18+J16*$AC$19+K16*$AC$20+L16*$AC$21+M16*$AC$22+N16*$AC$23+O16*$AC$24+P16*$AC$25+Q16*$AC$26+R16*$AC$27+S16*$AC$28+T16*$AC$29+U16*$AC$30 | W16: =1/(1+EXP(-V16)) | X16: =-IF(C16=1,LN(W16),LN(1-W16)) | Y16: =IF(W16>$AC$33,1,0) | Z16: =IF(Y16=C16,1,0) | AB16: installment_pct_income | AC16: 0.28721577 | AD16: 0.085070087 | AE16: =ABS(AC16) | AH16: total | AJ16: =AJ14+AJ15 | AK16: =AK14+AK15 | AL16: =AL14+AL15
A17: ='1 prepared data'!A10 | B17: ='1 prepared data'!U10 | C17: ='1 prepared data'!B10 | D17: ='1 prepared data'!C10 | E17: ='1 prepared data'!D10 | F17: ='1 prepared data'!E10 | G17: ='1 prepared data'!F10 | H17: ='1 prepared data'!G10 | I17: ='1 prepared data'!H10 | J17: ='1 prepared data'!I10 | ... U17: ='1 prepared data'!T10 | V17: =$AC$12+D17*$AC$13+E17*$AC$14+F17*$AC$15+G17*$AC$16+H17*$AC$17+I17*$AC$18+J17*$AC$19+K17*$AC$20+L17*$AC$21+M17*$AC$22+N17*$AC$23+O17*$AC$24+P17*$AC$25+Q17*$AC$26+R17*$AC$27+S17*$AC$28+T17*$AC$29+U17*$AC$30 | W17: =1/(1+EXP(-V17)) | X17: =-IF(C17=1,LN(W17),LN(1-W17)) | Y17: =IF(W17>$AC$33,1,0) | Z17: =IF(Y17=C17,1,0) | AB17: chk_negative | AC17: 1.5464027 | AD17: 0.97455047 | AE17: =ABS(AC17)
A18: ='1 prepared data'!A11 | B18: ='1 prepared data'!U11 | C18: ='1 prepared data'!B11 | D18: ='1 prepared data'!C11 | E18: ='1 prepared data'!D11 | F18: ='1 prepared data'!E11 | G18: ='1 prepared data'!F11 | H18: ='1 prepared data'!G11 | I18: ='1 prepared data'!H11 | J18: ='1 prepared data'!I11 | ... U18: ='1 prepared data'!T11 | V18: =$AC$12+D18*$AC$13+E18*$AC$14+F18*$AC$15+G18*$AC$16+H18*$AC$17+I18*$AC$18+J18*$AC$19+K18*$AC$20+L18*$AC$21+M18*$AC$22+N18*$AC$23+O18*$AC$24+P18*$AC$25+Q18*$AC$26+R18*$AC$27+S18*$AC$28+T18*$AC$29+U18*$AC$30 | W18: =1/(1+EXP(-V18)) | X18: =-IF(C18=1,LN(W18),LN(1-W18)) | Y18: =IF(W18>$AC$33,1,0) | Z18: =IF(Y18=C18,1,0) | AB18: chk_0_200 | AC18: 1.2949978 | AD18: 0.60995409 | AE18: =ABS(AC18) | AI18: precision | AJ18: recall | AK18: f1-score | AL18: support
A19: ='1 prepared data'!A12 | B19: ='1 prepared data'!U12 | C19: ='1 prepared data'!B12 | D19: ='1 prepared data'!C12 | E19: ='1 prepared data'!D12 | F19: ='1 prepared data'!E12 | G19: ='1 prepared data'!F12 | H19: ='1 prepared data'!G12 | I19: ='1 prepared data'!H12 | J19: ='1 prepared data'!I12 | ... U19: ='1 prepared data'!T12 | V19: =$AC$12+D19*$AC$13+E19*$AC$14+F19*$AC$15+G19*$AC$16+H19*$AC$17+I19*$AC$18+J19*$AC$19+K19*$AC$20+L19*$AC$21+M19*$AC$22+N19*$AC$23+O19*$AC$24+P19*$AC$25+Q19*$AC$26+R19*$AC$27+S19*$AC$28+T19*$AC$29+U19*$AC$30 | W19: =1/(1+EXP(-V19)) | X19: =-IF(C19=1,LN(W19),LN(1-W19)) | Y19: =IF(W19>$AC$33,1,0) | Z19: =IF(Y19=C19,1,0) | AB19: chk_over_200 | AC19: 0.66836159 | AD19: 0 | AE19: =ABS(AC19) | AH19: class 0 (pays) | AI19: =IF(AJ14+AJ15=0,0,AJ14/(AJ14+AJ15)) | AJ19: =IF(AJ14+AK14=0,0,AJ14/(AJ14+AK14)) | AK19: =IF(AI19+AJ19=0,0,2*AI19*AJ19/(AI19+AJ19)) | AL19: =AL14
A20: ='1 prepared data'!A13 | B20: ='1 prepared data'!U13 | C20: ='1 prepared data'!B13 | D20: ='1 prepared data'!C13 | E20: ='1 prepared data'!D13 | F20: ='1 prepared data'!E13 | G20: ='1 prepared data'!F13 | H20: ='1 prepared data'!G13 | I20: ='1 prepared data'!H13 | J20: ='1 prepared data'!I13 | ... U20: ='1 prepared data'!T13 | V20: =$AC$12+D20*$AC$13+E20*$AC$14+F20*$AC$15+G20*$AC$16+H20*$AC$17+I20*$AC$18+J20*$AC$19+K20*$AC$20+L20*$AC$21+M20*$AC$22+N20*$AC$23+O20*$AC$24+P20*$AC$25+Q20*$AC$26+R20*$AC$27+S20*$AC$28+T20*$AC$29+U20*$AC$30 | W20: =1/(1+EXP(-V20)) | X20: =-IF(C20=1,LN(W20),LN(1-W20)) | Y20: =IF(W20>$AC$33,1,0) | Z20: =IF(Y20=C20,1,0) | AB20: hist_critical | AC20: -0.65734494 | AD20: -0.35469615 | AE20: =ABS(AC20) | AH20: class 1 (defaults) | AI20: =IF(AK15+AK14=0,0,AK15/(AK15+AK14)) | AJ20: =IF(AK15+AJ15=0,0,AK15/(AK15+AJ15)) | AK20: =IF(AI20+AJ20=0,0,2*AI20*AJ20/(AI20+AJ20)) | AL20: =AL15
A21: ='1 prepared data'!A14 | B21: ='1 prepared data'!U14 | C21: ='1 prepared data'!B14 | D21: ='1 prepared data'!C14 | E21: ='1 prepared data'!D14 | F21: ='1 prepared data'!E14 | G21: ='1 prepared data'!F14 | H21: ='1 prepared data'!G14 | I21: ='1 prepared data'!H14 | J21: ='1 prepared data'!I14 | ... U21: ='1 prepared data'!T14 | V21: =$AC$12+D21*$AC$13+E21*$AC$14+F21*$AC$15+G21*$AC$16+H21*$AC$17+I21*$AC$18+J21*$AC$19+K21*$AC$20+L21*$AC$21+M21*$AC$22+N21*$AC$23+O21*$AC$24+P21*$AC$25+Q21*$AC$26+R21*$AC$27+S21*$AC$28+T21*$AC$29+U21*$AC$30 | W21: =1/(1+EXP(-V21)) | X21: =-IF(C21=1,LN(W21),LN(1-W21)) | Y21: =IF(W21>$AC$33,1,0) | Z21: =IF(Y21=C21,1,0) | AB21: hist_delays | AC21: -0.040195519 | AD21: 0 | AE21: =ABS(AC21) | AH21: accuracy | AK21: =(AK15+AJ14)/AL16
A22: ='1 prepared data'!A15 | B22: ='1 prepared data'!U15 | C22: ='1 prepared data'!B15 | D22: ='1 prepared data'!C15 | E22: ='1 prepared data'!D15 | F22: ='1 prepared data'!E15 | G22: ='1 prepared data'!F15 | H22: ='1 prepared data'!G15 | I22: ='1 prepared data'!H15 | J22: ='1 prepared data'!I15 | ... U22: ='1 prepared data'!T15 | V22: =$AC$12+D22*$AC$13+E22*$AC$14+F22*$AC$15+G22*$AC$16+H22*$AC$17+I22*$AC$18+J22*$AC$19+K22*$AC$20+L22*$AC$21+M22*$AC$22+N22*$AC$23+O22*$AC$24+P22*$AC$25+Q22*$AC$26+R22*$AC$27+S22*$AC$28+T22*$AC$29+U22*$AC$30 | W22: =1/(1+EXP(-V22)) | X22: =-IF(C22=1,LN(W22),LN(1-W22)) | Y22: =IF(W22>$AC$33,1,0) | Z22: =IF(Y22=C22,1,0) | AB22: hist_no_credits | AC22: 0.66906563 | AD22: 0.15570542 | AE22: =ABS(AC22)
A23: ='1 prepared data'!A16 | B23: ='1 prepared data'!U16 | C23: ='1 prepared data'!B16 | D23: ='1 prepared data'!C16 | E23: ='1 prepared data'!D16 | F23: ='1 prepared data'!E16 | G23: ='1 prepared data'!F16 | H23: ='1 prepared data'!G16 | I23: ='1 prepared data'!H16 | J23: ='1 prepared data'!I16 | ... U23: ='1 prepared data'!T16 | V23: =$AC$12+D23*$AC$13+E23*$AC$14+F23*$AC$15+G23*$AC$16+H23*$AC$17+I23*$AC$18+J23*$AC$19+K23*$AC$20+L23*$AC$21+M23*$AC$22+N23*$AC$23+O23*$AC$24+P23*$AC$25+Q23*$AC$26+R23*$AC$27+S23*$AC$28+T23*$AC$29+U23*$AC$30 | W23: =1/(1+EXP(-V23)) | X23: =-IF(C23=1,LN(W23),LN(1-W23)) | Y23: =IF(W23>$AC$33,1,0) | Z23: =IF(Y23=C23,1,0) | AB23: sav_100_1000 | AC23: -0.38958343 | AD23: 0 | AE23: =ABS(AC23)
A24: ='1 prepared data'!A17 | B24: ='1 prepared data'!U17 | C24: ='1 prepared data'!B17 | D24: ='1 prepared data'!C17 | E24: ='1 prepared data'!D17 | F24: ='1 prepared data'!E17 | G24: ='1 prepared data'!F17 | H24: ='1 prepared data'!G17 | I24: ='1 prepared data'!H17 | J24: ='1 prepared data'!I17 | ... U24: ='1 prepared data'!T17 | V24: =$AC$12+D24*$AC$13+E24*$AC$14+F24*$AC$15+G24*$AC$16+H24*$AC$17+I24*$AC$18+J24*$AC$19+K24*$AC$20+L24*$AC$21+M24*$AC$22+N24*$AC$23+O24*$AC$24+P24*$AC$25+Q24*$AC$26+R24*$AC$27+S24*$AC$28+T24*$AC$29+U24*$AC$30 | W24: =1/(1+EXP(-V24)) | X24: =-IF(C24=1,LN(W24),LN(1-W24)) | Y24: =IF(W24>$AC$33,1,0) | Z24: =IF(Y24=C24,1,0) | AB24: sav_over_1000 | AC24: -0.88922386 | AD24: 0 | AE24: =ABS(AC24)
A25: ='1 prepared data'!A18 | B25: ='1 prepared data'!U18 | C25: ='1 prepared data'!B18 | D25: ='1 prepared data'!C18 | E25: ='1 prepared data'!D18 | F25: ='1 prepared data'!E18 | G25: ='1 prepared data'!F18 | H25: ='1 prepared data'!G18 | I25: ='1 prepared data'!H18 | J25: ='1 prepared data'!I18 | ... U25: ='1 prepared data'!T18 | V25: =$AC$12+D25*$AC$13+E25*$AC$14+F25*$AC$15+G25*$AC$16+H25*$AC$17+I25*$AC$18+J25*$AC$19+K25*$AC$20+L25*$AC$21+M25*$AC$22+N25*$AC$23+O25*$AC$24+P25*$AC$25+Q25*$AC$26+R25*$AC$27+S25*$AC$28+T25*$AC$29+U25*$AC$30 | W25: =1/(1+EXP(-V25)) | X25: =-IF(C25=1,LN(W25),LN(1-W25)) | Y25: =IF(W25>$AC$33,1,0) | Z25: =IF(Y25=C25,1,0) | AB25: sav_unknown | AC25: -1.0760929 | AD25: -0.23308747 | AE25: =ABS(AC25)
A26: ='1 prepared data'!A19 | B26: ='1 prepared data'!U19 | C26: ='1 prepared data'!B19 | D26: ='1 prepared data'!C19 | E26: ='1 prepared data'!D19 | F26: ='1 prepared data'!E19 | G26: ='1 prepared data'!F19 | H26: ='1 prepared data'!G19 | I26: ='1 prepared data'!H19 | J26: ='1 prepared data'!I19 | ... U26: ='1 prepared data'!T19 | V26: =$AC$12+D26*$AC$13+E26*$AC$14+F26*$AC$15+G26*$AC$16+H26*$AC$17+I26*$AC$18+J26*$AC$19+K26*$AC$20+L26*$AC$21+M26*$AC$22+N26*$AC$23+O26*$AC$24+P26*$AC$25+Q26*$AC$26+R26*$AC$27+S26*$AC$28+T26*$AC$29+U26*$AC$30 | W26: =1/(1+EXP(-V26)) | X26: =-IF(C26=1,LN(W26),LN(1-W26)) | Y26: =IF(W26>$AC$33,1,0) | Z26: =IF(Y26=C26,1,0) | AB26: housing_rent | AC26: 0.65383718 | AD26: 0.084128659 | AE26: =ABS(AC26)
A27: ='1 prepared data'!A20 | B27: ='1 prepared data'!U20 | C27: ='1 prepared data'!B20 | D27: ='1 prepared data'!C20 | E27: ='1 prepared data'!D20 | F27: ='1 prepared data'!E20 | G27: ='1 prepared data'!F20 | H27: ='1 prepared data'!G20 | I27: ='1 prepared data'!H20 | J27: ='1 prepared data'!I20 | ... U27: ='1 prepared data'!T20 | V27: =$AC$12+D27*$AC$13+E27*$AC$14+F27*$AC$15+G27*$AC$16+H27*$AC$17+I27*$AC$18+J27*$AC$19+K27*$AC$20+L27*$AC$21+M27*$AC$22+N27*$AC$23+O27*$AC$24+P27*$AC$25+Q27*$AC$26+R27*$AC$27+S27*$AC$28+T27*$AC$29+U27*$AC$30 | W27: =1/(1+EXP(-V27)) | X27: =-IF(C27=1,LN(W27),LN(1-W27)) | Y27: =IF(W27>$AC$33,1,0) | Z27: =IF(Y27=C27,1,0) | AB27: housing_free | AC27: 0.19536536 | AD27: 0 | AE27: =ABS(AC27)
A28: ='1 prepared data'!A21 | B28: ='1 prepared data'!U21 | C28: ='1 prepared data'!B21 | D28: ='1 prepared data'!C21 | E28: ='1 prepared data'!D21 | F28: ='1 prepared data'!E21 | G28: ='1 prepared data'!F21 | H28: ='1 prepared data'!G21 | I28: ='1 prepared data'!H21 | J28: ='1 prepared data'!I21 | ... U28: ='1 prepared data'!T21 | V28: =$AC$12+D28*$AC$13+E28*$AC$14+F28*$AC$15+G28*$AC$16+H28*$AC$17+I28*$AC$18+J28*$AC$19+K28*$AC$20+L28*$AC$21+M28*$AC$22+N28*$AC$23+O28*$AC$24+P28*$AC$25+Q28*$AC$26+R28*$AC$27+S28*$AC$28+T28*$AC$29+U28*$AC$30 | W28: =1/(1+EXP(-V28)) | X28: =-IF(C28=1,LN(W28),LN(1-W28)) | Y28: =IF(W28>$AC$33,1,0) | Z28: =IF(Y28=C28,1,0) | AB28: purpose_car | AC28: -0.080165476 | AD28: 0 | AE28: =ABS(AC28)
A29: ='1 prepared data'!A22 | B29: ='1 prepared data'!U22 | C29: ='1 prepared data'!B22 | D29: ='1 prepared data'!C22 | E29: ='1 prepared data'!D22 | F29: ='1 prepared data'!E22 | G29: ='1 prepared data'!F22 | H29: ='1 prepared data'!G22 | I29: ='1 prepared data'!H22 | J29: ='1 prepared data'!I22 | ... U29: ='1 prepared data'!T22 | V29: =$AC$12+D29*$AC$13+E29*$AC$14+F29*$AC$15+G29*$AC$16+H29*$AC$17+I29*$AC$18+J29*$AC$19+K29*$AC$20+L29*$AC$21+M29*$AC$22+N29*$AC$23+O29*$AC$24+P29*$AC$25+Q29*$AC$26+R29*$AC$27+S29*$AC$28+T29*$AC$29+U29*$AC$30 | W29: =1/(1+EXP(-V29)) | X29: =-IF(C29=1,LN(W29),LN(1-W29)) | Y29: =IF(W29>$AC$33,1,0) | Z29: =IF(Y29=C29,1,0) | AB29: purpose_radio_tv | AC29: -0.52021065 | AD29: -0.064936381 | AE29: =ABS(AC29)
A30: ='1 prepared data'!A23 | B30: ='1 prepared data'!U23 | C30: ='1 prepared data'!B23 | D30: ='1 prepared data'!C23 | E30: ='1 prepared data'!D23 | F30: ='1 prepared data'!E23 | G30: ='1 prepared data'!F23 | H30: ='1 prepared data'!G23 | I30: ='1 prepared data'!H23 | J30: ='1 prepared data'!I23 | ... U30: ='1 prepared data'!T23 | V30: =$AC$12+D30*$AC$13+E30*$AC$14+F30*$AC$15+G30*$AC$16+H30*$AC$17+I30*$AC$18+J30*$AC$19+K30*$AC$20+L30*$AC$21+M30*$AC$22+N30*$AC$23+O30*$AC$24+P30*$AC$25+Q30*$AC$26+R30*$AC$27+S30*$AC$28+T30*$AC$29+U30*$AC$30 | W30: =1/(1+EXP(-V30)) | X30: =-IF(C30=1,LN(W30),LN(1-W30)) | Y30: =IF(W30>$AC$33,1,0) | Z30: =IF(Y30=C30,1,0) | AB30: purpose_furniture | AC30: -0.28180274 | AD30: 0 | AE30: =ABS(AC30)
A31: ='1 prepared data'!A24 | B31: ='1 prepared data'!U24 | C31: ='1 prepared data'!B24 | D31: ='1 prepared data'!C24 | E31: ='1 prepared data'!D24 | F31: ='1 prepared data'!E24 | G31: ='1 prepared data'!F24 | H31: ='1 prepared data'!G24 | I31: ='1 prepared data'!H24 | J31: ='1 prepared data'!I24 | ... U31: ='1 prepared data'!T24 | V31: =$AC$12+D31*$AC$13+E31*$AC$14+F31*$AC$15+G31*$AC$16+H31*$AC$17+I31*$AC$18+J31*$AC$19+K31*$AC$20+L31*$AC$21+M31*$AC$22+N31*$AC$23+O31*$AC$24+P31*$AC$25+Q31*$AC$26+R31*$AC$27+S31*$AC$28+T31*$AC$29+U31*$AC$30 | W31: =1/(1+EXP(-V31)) | X31: =-IF(C31=1,LN(W31),LN(1-W31)) | Y31: =IF(W31>$AC$33,1,0) | Z31: =IF(Y31=C31,1,0)
A32: ='1 prepared data'!A25 | B32: ='1 prepared data'!U25 | C32: ='1 prepared data'!B25 | D32: ='1 prepared data'!C25 | E32: ='1 prepared data'!D25 | F32: ='1 prepared data'!E25 | G32: ='1 prepared data'!F25 | H32: ='1 prepared data'!G25 | I32: ='1 prepared data'!H25 | J32: ='1 prepared data'!I25 | ... U32: ='1 prepared data'!T25 | V32: =$AC$12+D32*$AC$13+E32*$AC$14+F32*$AC$15+G32*$AC$16+H32*$AC$17+I32*$AC$18+J32*$AC$19+K32*$AC$20+L32*$AC$21+M32*$AC$22+N32*$AC$23+O32*$AC$24+P32*$AC$25+Q32*$AC$26+R32*$AC$27+S32*$AC$28+T32*$AC$29+U32*$AC$30 | W32: =1/(1+EXP(-V32)) | X32: =-IF(C32=1,LN(W32),LN(1-W32)) | Y32: =IF(W32>$AC$33,1,0) | Z32: =IF(Y32=C32,1,0) | AB32: λ (lambda): how much the size of the weights costs | AC32: 10
A33: ='1 prepared data'!A26 | B33: ='1 prepared data'!U26 | C33: ='1 prepared data'!B26 | D33: ='1 prepared data'!C26 | E33: ='1 prepared data'!D26 | F33: ='1 prepared data'!E26 | G33: ='1 prepared data'!F26 | H33: ='1 prepared data'!G26 | I33: ='1 prepared data'!H26 | J33: ='1 prepared data'!I26 | ... U33: ='1 prepared data'!T26 | V33: =$AC$12+D33*$AC$13+E33*$AC$14+F33*$AC$15+G33*$AC$16+H33*$AC$17+I33*$AC$18+J33*$AC$19+K33*$AC$20+L33*$AC$21+M33*$AC$22+N33*$AC$23+O33*$AC$24+P33*$AC$25+Q33*$AC$26+R33*$AC$27+S33*$AC$28+T33*$AC$29+U33*$AC$30 | W33: =1/(1+EXP(-V33)) | X33: =-IF(C33=1,LN(W33),LN(1-W33)) | Y33: =IF(W33>$AC$33,1,0) | Z33: =IF(Y33=C33,1,0) | AB33: threshold | AC33: 0.5
A34: ='1 prepared data'!A27 | B34: ='1 prepared data'!U27 | C34: ='1 prepared data'!B27 | D34: ='1 prepared data'!C27 | E34: ='1 prepared data'!D27 | F34: ='1 prepared data'!E27 | G34: ='1 prepared data'!F27 | H34: ='1 prepared data'!G27 | I34: ='1 prepared data'!H27 | J34: ='1 prepared data'!I27 | ... U34: ='1 prepared data'!T27 | V34: =$AC$12+D34*$AC$13+E34*$AC$14+F34*$AC$15+G34*$AC$16+H34*$AC$17+I34*$AC$18+J34*$AC$19+K34*$AC$20+L34*$AC$21+M34*$AC$22+N34*$AC$23+O34*$AC$24+P34*$AC$25+Q34*$AC$26+R34*$AC$27+S34*$AC$28+T34*$AC$29+U34*$AC$30 | W34: =1/(1+EXP(-V34)) | X34: =-IF(C34=1,LN(W34),LN(1-W34)) | Y34: =IF(W34>$AC$33,1,0) | Z34: =IF(Y34=C34,1,0)
A35: ='1 prepared data'!A28 | B35: ='1 prepared data'!U28 | C35: ='1 prepared data'!B28 | D35: ='1 prepared data'!C28 | E35: ='1 prepared data'!D28 | F35: ='1 prepared data'!E28 | G35: ='1 prepared data'!F28 | H35: ='1 prepared data'!G28 | I35: ='1 prepared data'!H28 | J35: ='1 prepared data'!I28 | ... U35: ='1 prepared data'!T28 | V35: =$AC$12+D35*$AC$13+E35*$AC$14+F35*$AC$15+G35*$AC$16+H35*$AC$17+I35*$AC$18+J35*$AC$19+K35*$AC$20+L35*$AC$21+M35*$AC$22+N35*$AC$23+O35*$AC$24+P35*$AC$25+Q35*$AC$26+R35*$AC$27+S35*$AC$28+T35*$AC$29+U35*$AC$30 | W35: =1/(1+EXP(-V35)) | X35: =-IF(C35=1,LN(W35),LN(1-W35)) | Y35: =IF(W35>$AC$33,1,0) | Z35: =IF(Y35=C35,1,0) | AB35: RESULTS
A36: ='1 prepared data'!A29 | B36: ='1 prepared data'!U29 | C36: ='1 prepared data'!B29 | D36: ='1 prepared data'!C29 | E36: ='1 prepared data'!D29 | F36: ='1 prepared data'!E29 | G36: ='1 prepared data'!F29 | H36: ='1 prepared data'!G29 | I36: ='1 prepared data'!H29 | J36: ='1 prepared data'!I29 | ... U36: ='1 prepared data'!T29 | V36: =$AC$12+D36*$AC$13+E36*$AC$14+F36*$AC$15+G36*$AC$16+H36*$AC$17+I36*$AC$18+J36*$AC$19+K36*$AC$20+L36*$AC$21+M36*$AC$22+N36*$AC$23+O36*$AC$24+P36*$AC$25+Q36*$AC$26+R36*$AC$27+S36*$AC$28+T36*$AC$29+U36*$AC$30 | W36: =1/(1+EXP(-V36)) | X36: =-IF(C36=1,LN(W36),LN(1-W36)) | Y36: =IF(W36>$AC$33,1,0) | Z36: =IF(Y36=C36,1,0) | AB36: sum of training losses | AC36: =SUMPRODUCT(($B$12:$B$1011="training")*$X$12:$X$1011)
A37: ='1 prepared data'!A30 | B37: ='1 prepared data'!U30 | C37: ='1 prepared data'!B30 | D37: ='1 prepared data'!C30 | E37: ='1 prepared data'!D30 | F37: ='1 prepared data'!E30 | G37: ='1 prepared data'!F30 | H37: ='1 prepared data'!G30 | I37: ='1 prepared data'!H30 | J37: ='1 prepared data'!I30 | ... U37: ='1 prepared data'!T30 | V37: =$AC$12+D37*$AC$13+E37*$AC$14+F37*$AC$15+G37*$AC$16+H37*$AC$17+I37*$AC$18+J37*$AC$19+K37*$AC$20+L37*$AC$21+M37*$AC$22+N37*$AC$23+O37*$AC$24+P37*$AC$25+Q37*$AC$26+R37*$AC$27+S37*$AC$28+T37*$AC$29+U37*$AC$30 | W37: =1/(1+EXP(-V37)) | X37: =-IF(C37=1,LN(W37),LN(1-W37)) | Y37: =IF(W37>$AC$33,1,0) | Z37: =IF(Y37=C37,1,0) | AB37: L1 penalty = λ · Σ |theta| | AC37: =$AC$32*SUM($AE$13:$AE$30)
A38: ='1 prepared data'!A31 | B38: ='1 prepared data'!U31 | C38: ='1 prepared data'!B31 | D38: ='1 prepared data'!C31 | E38: ='1 prepared data'!D31 | F38: ='1 prepared data'!E31 | G38: ='1 prepared data'!F31 | H38: ='1 prepared data'!G31 | I38: ='1 prepared data'!H31 | J38: ='1 prepared data'!I31 | ... U38: ='1 prepared data'!T31 | V38: =$AC$12+D38*$AC$13+E38*$AC$14+F38*$AC$15+G38*$AC$16+H38*$AC$17+I38*$AC$18+J38*$AC$19+K38*$AC$20+L38*$AC$21+M38*$AC$22+N38*$AC$23+O38*$AC$24+P38*$AC$25+Q38*$AC$26+R38*$AC$27+S38*$AC$28+T38*$AC$29+U38*$AC$30 | W38: =1/(1+EXP(-V38)) | X38: =-IF(C38=1,LN(W38),LN(1-W38)) | Y38: =IF(W38>$AC$33,1,0) | Z38: =IF(Y38=C38,1,0) | AB38: J = sum of losses + penalty (SOLVER OBJECTIVE) | AC38: =AC36+AC37
A39: ='1 prepared data'!A32 | B39: ='1 prepared data'!U32 | C39: ='1 prepared data'!B32 | D39: ='1 prepared data'!C32 | E39: ='1 prepared data'!D32 | F39: ='1 prepared data'!E32 | G39: ='1 prepared data'!F32 | H39: ='1 prepared data'!G32 | I39: ='1 prepared data'!H32 | J39: ='1 prepared data'!I32 | ... U39: ='1 prepared data'!T32 | V39: =$AC$12+D39*$AC$13+E39*$AC$14+F39*$AC$15+G39*$AC$16+H39*$AC$17+I39*$AC$18+J39*$AC$19+K39*$AC$20+L39*$AC$21+M39*$AC$22+N39*$AC$23+O39*$AC$24+P39*$AC$25+Q39*$AC$26+R39*$AC$27+S39*$AC$28+T39*$AC$29+U39*$AC$30 | W39: =1/(1+EXP(-V39)) | X39: =-IF(C39=1,LN(W39),LN(1-W39)) | Y39: =IF(W39>$AC$33,1,0) | Z39: =IF(Y39=C39,1,0) | AB39: average training loss | AC39: =AC36/COUNTIF($B$12:$B$1011,"training")
A40: ='1 prepared data'!A33 | B40: ='1 prepared data'!U33 | C40: ='1 prepared data'!B33 | D40: ='1 prepared data'!C33 | E40: ='1 prepared data'!D33 | F40: ='1 prepared data'!E33 | G40: ='1 prepared data'!F33 | H40: ='1 prepared data'!G33 | I40: ='1 prepared data'!H33 | J40: ='1 prepared data'!I33 | ... U40: ='1 prepared data'!T33 | V40: =$AC$12+D40*$AC$13+E40*$AC$14+F40*$AC$15+G40*$AC$16+H40*$AC$17+I40*$AC$18+J40*$AC$19+K40*$AC$20+L40*$AC$21+M40*$AC$22+N40*$AC$23+O40*$AC$24+P40*$AC$25+Q40*$AC$26+R40*$AC$27+S40*$AC$28+T40*$AC$29+U40*$AC$30 | W40: =1/(1+EXP(-V40)) | X40: =-IF(C40=1,LN(W40),LN(1-W40)) | Y40: =IF(W40>$AC$33,1,0) | Z40: =IF(Y40=C40,1,0) | AB40: average testing loss | AC40: =SUMPRODUCT(($B$12:$B$1011="testing")*$X$12:$X$1011)/COUNTIF($B$12:$B$1011,"testing")
A41: ='1 prepared data'!A34 | B41: ='1 prepared data'!U34 | C41: ='1 prepared data'!B34 | D41: ='1 prepared data'!C34 | E41: ='1 prepared data'!D34 | F41: ='1 prepared data'!E34 | G41: ='1 prepared data'!F34 | H41: ='1 prepared data'!G34 | I41: ='1 prepared data'!H34 | J41: ='1 prepared data'!I34 | ... U41: ='1 prepared data'!T34 | V41: =$AC$12+D41*$AC$13+E41*$AC$14+F41*$AC$15+G41*$AC$16+H41*$AC$17+I41*$AC$18+J41*$AC$19+K41*$AC$20+L41*$AC$21+M41*$AC$22+N41*$AC$23+O41*$AC$24+P41*$AC$25+Q41*$AC$26+R41*$AC$27+S41*$AC$28+T41*$AC$29+U41*$AC$30 | W41: =1/(1+EXP(-V41)) | X41: =-IF(C41=1,LN(W41),LN(1-W41)) | Y41: =IF(W41>$AC$33,1,0) | Z41: =IF(Y41=C41,1,0) | AB41: testing accuracy | AC41: =SUMPRODUCT(($B$12:$B$1011="testing")*$Z$12:$Z$1011)/COUNTIF($B$12:$B$1011,"testing")
